<?xml version="1.0" ?>
<!-- =================================================================================== -->
<!-- |    This document was autogenerated by xacro from poli_wrapper.urdf.xacro        | -->
<!-- |    EDITING THIS FILE BY HAND IS NOT RECOMMENDED                                 | -->
<!-- =================================================================================== -->
<robot name="segway_robot" xmlns:body="http://playerstage.sourceforge.net/gazebo/xmlschema/#body" xmlns:controller="http://playerstage.sourceforge.net/gazebo/xmlschema/#controller" xmlns:gazebo="http://playerstage.sourceforge.net/gazebo/xmlschema/#gz" xmlns:geom="http://playerstage.sourceforge.net/gazebo/xmlschema/#geom" xmlns:interface="http://playerstage.sourceforge.net/gazebo/xmlschema/#interface" xmlns:joint="http://playerstage.sourceforge.net/gazebo/xmlschema/#joint" xmlns:model="http://playerstage.sourceforge.net/gazebo/xmlschema/#model" xmlns:physics="http://playerstage.sourceforge.net/gazebo/xmlschema/#physics" xmlns:renderable="http://playerstage.sourceforge.net/gazebo/xmlschema/#renderable" xmlns:rendering="http://playerstage.sourceforge.net/gazebo/xmlschema/#rendering" xmlns:sensor="http://playerstage.sourceforge.net/gazebo/xmlschema/#sensor" xmlns:xacro="http://ros.org/wiki/xacro" xmlns:xi="http://www.w3.org/2001/XInclude">
  <!-- links      		mesh_no
   base           		0
   shoulder       		1
   arm            		2
   forearm        		3
   wrist          		4
   arm_mico       		5
   arm_half1 (7dof)		6
   arm_half2 (7dof)		7
   wrist_spherical_1  8
   wrist_spherical_2  9

   hand 3 finger  		55
   hand_2finger   		56
   finger_proximal		57
   finger_distal      58 
-->
  <!-- links      		mesh_no
   base           		0
   shoulder       		1
   arm            		2
   forearm        		3
   wrist          		4
   arm_mico       		5
   arm_half1 (7dof)		6
   arm_half2 (7dof)		7
   wrist_spherical_1  8
   wrist_spherical_2  9

   hand 3 finger  		55
   hand_2finger   		56
   finger_proximal		57
   finger_distal      58 
-->
  <!-- links      		mesh_no
   base           		0
   shoulder       		1
   arm            		2
   forearm        		3
   wrist          		4
   arm_mico       		5
   arm_half1 (7dof)		6
   arm_half2 (7dof)		7
   wrist_spherical_1  8
   wrist_spherical_2  9

   hand 3 finger  		55
   hand_2finger   		56
   finger_proximal		57
   finger_distal      58 
-->
  <gazebo>
    <plugin filename="libgazebo_ros_control.so" name="gazebo_ros_control">
      <robotNamespace>/</robotNamespace>
    </plugin>
    <plugin filename="libgazebo_ros_force_based_move.so" name="object_controller">
      <commandTopic>/cmd_vel</commandTopic>
      <odometryTopic>/odom</odometryTopic>
      <odometryFrame>odom</odometryFrame>
      <odometryRate>30.0</odometryRate>
      <robotBaseFrame>base_link</robotBaseFrame>
      <publishOdometryTf>1</publishOdometryTf>
      <yaw_velocity_p_gain>100.0</yaw_velocity_p_gain>
      <x_velocity_p_gain>10000.0</x_velocity_p_gain>
      <y_velocity_p_gain>10000.0</y_velocity_p_gain>
    </plugin>
  </gazebo>
  <!-- Base link is the center of the robot's chassis between the motors projected on the ground -->
  <link name="base_link"/>
  <joint name="base_chassis_joint" type="fixed">
    <origin rpy="0 0 0" xyz="0 0 0.15801795"/>
    <parent link="base_link"/>
    <child link="base_chassis_link"/>
  </joint>
  <link name="base_chassis_link">
    <visual>
      <geometry>
        <mesh filename="package://poli2_description/meshes/visual/110_powerbase.dae"/>
      </geometry>
    </visual>
  </link>
  <link name="inertial_collision_link">
    <inertial>
      <mass value="29.756375"/>
      <origin xyz="0.001751 0.000008 0.018544"/>
      <inertia ixx="0.696269" ixy="0.016133" ixz="0.003232" iyx="0.016133" iyy="0.299110" iyz="-0.000004" izx="-0.077476" izy="-0.000004" izz="0.864394"/>
    </inertial>
    <collision>
      <geometry>
        <mesh filename="package://poli2_description/meshes/collision/110_powerbase_collision.stl"/>
      </geometry>
    </collision>
  </link>
  <joint name="inertial_collision_joint" type="fixed">
    <parent link="base_chassis_link"/>
    <child link="inertial_collision_link"/>
  </joint>
  <joint name="mcu_1_battery_joint" type="fixed">
    <origin rpy="0 0 0" xyz="-0.09298 0 0"/>
    <parent link="base_chassis_link"/>
    <child link="mcu_1_battery_link"/>
  </joint>
  <link name="mcu_1_battery_link">
    <visual>
      <geometry>
        <mesh filename="package://poli2_description/meshes/visual/battery.dae"/>
      </geometry>
    </visual>
  </link>
  <joint name="aux_battery_joint" type="fixed">
    <origin rpy="0 0 3.14159" xyz="0.09298 0 0"/>
    <parent link="base_chassis_link"/>
    <child link="aux_battery_link"/>
  </joint>
  <link name="aux_battery_link">
    <visual>
      <geometry>
        <mesh filename="package://poli2_description/meshes/visual/battery.dae"/>
      </geometry>
    </visual>
  </link>
  <joint name="hmi_joint" type="fixed">
    <origin rpy="0 0 0" xyz="0 0 0.09504494"/>
    <parent link="base_chassis_link"/>
    <child link="hmi_link"/>
  </joint>
  <link name="hmi_link">
    <visual>
      <geometry>
        <mesh filename="package://poli2_description/meshes/visual/110_hmi_box.dae"/>
      </geometry>
    </visual>
    <collision>
      <geometry>
        <mesh filename="package://poli2_description/meshes/collision/110_hmi_box_collision.stl"/>
      </geometry>
    </collision>
    <inertial>
      <mass value="0.078971"/>
      <origin xyz="-0.000022 -0.000090 0.035623"/>
      <inertia ixx="0.000082" ixy="0.000000" ixz="0.000000" iyx="0.000000" iyy="0.000081" iyz="-0.000001" izx="0.000000" izy="-0.000001" izz="0.000103"/>
    </inertial>
  </link>
  <joint name="hmi_plate_joint" type="fixed">
    <origin rpy="0 0 0" xyz="0 0 0"/>
    <parent link="hmi_link"/>
    <child link="hmi_plate_link"/>
  </joint>
  <link name="hmi_plate_link">
    <visual>
      <geometry>
        <mesh filename="package://poli2_description/meshes/visual/110_hmi_plate.dae"/>
      </geometry>
    </visual>
  </link>
  <link name="left_wheel_link">
    <inertial>
      <mass value="4.195729"/>
      <origin xyz="0 0 0"/>
      <inertia ixx="0.063680" ixy="0.000000" ixz="0.000000" iyx="0.000000" iyy="0.121410" iyz="0.000000" izx="0.000000" izy="0.000000" izz="0.063680"/>
    </inertial>
    <visual>
      <origin rpy="0 0 0.0" xyz="0 0 0"/>
      <geometry>
        <mesh filename="package://poli2_description/meshes/visual/i2_wheel.dae"/>
      </geometry>
    </visual>
    <collision>
      <origin rpy="1.570795 0 0" xyz="0 0 0"/>
      <geometry>
        <cylinder length="0.092249" radius="0.2405681"/>
      </geometry>
    </collision>
  </link>
  <gazebo reference="left_wheel_link">
    <mu1 value="10.0"/>
    <mu2 value="10.0"/>
    <kp value="10000000.0"/>
    <kd value="10.0"/>
    <fdir1 value="1 0 0"/>
    <minDepth>0.003</minDepth>
  </gazebo>
  <joint name="left_wheel" type="continuous">
    <parent link="base_chassis_link"/>
    <child link="left_wheel_link"/>
    <origin rpy="0 0 0" xyz="0 0.2406122 0.08255015"/>
    <axis rpy="0 0 0" xyz="0 1 0"/>
  </joint>
  <transmission name="left_wheel_trans" type="SimpleTransmission">
    <type>transmission_interface/SimpleTransmission</type>
    <actuator name="left_wheel_motor">
      <mechanicalReduction>1</mechanicalReduction>
    </actuator>
    <joint name="left_wheel">
      <hardwareInterface>VelocityJointInterface</hardwareInterface>
    </joint>
  </transmission>
  <link name="right_wheel_link">
    <inertial>
      <mass value="4.195729"/>
      <origin xyz="0 0 0"/>
      <inertia ixx="0.063680" ixy="0.000000" ixz="0.000000" iyx="0.000000" iyy="0.121410" iyz="0.000000" izx="0.000000" izy="0.000000" izz="0.063680"/>
    </inertial>
    <visual>
      <origin rpy="0 0 3.14159" xyz="0 0 0"/>
      <geometry>
        <mesh filename="package://poli2_description/meshes/visual/i2_wheel.dae"/>
      </geometry>
    </visual>
    <collision>
      <origin rpy="1.570795 0 0" xyz="0 0 0"/>
      <geometry>
        <cylinder length="0.092249" radius="0.2405681"/>
      </geometry>
    </collision>
  </link>
  <gazebo reference="right_wheel_link">
    <mu1 value="10.0"/>
    <mu2 value="10.0"/>
    <kp value="10000000.0"/>
    <kd value="10.0"/>
    <fdir1 value="1 0 0"/>
    <minDepth>0.003</minDepth>
  </gazebo>
  <joint name="right_wheel" type="continuous">
    <parent link="base_chassis_link"/>
    <child link="right_wheel_link"/>
    <origin rpy="0 0 0" xyz="0 -0.2406122 0.08255015"/>
    <axis rpy="0 0 0" xyz="0 1 0"/>
  </joint>
  <transmission name="right_wheel_trans" type="SimpleTransmission">
    <type>transmission_interface/SimpleTransmission</type>
    <actuator name="right_wheel_motor">
      <mechanicalReduction>1</mechanicalReduction>
    </actuator>
    <joint name="right_wheel">
      <hardwareInterface>VelocityJointInterface</hardwareInterface>
    </joint>
  </transmission>
  <joint name="rear_caster_plate_joint" type="fixed">
    <origin rpy="0 0 3.14159" xyz="-0.32784550 0 0.03326933"/>
    <parent link="base_chassis_link"/>
    <child link="rear_caster_plate_link"/>
  </joint>
  <link name="rear_caster_plate_link">
    <inertial>
      <mass value="3.836"/>
      <origin xyz="0.060136 -8.6661E-08 0.039089"/>
      <inertia ixx="0.047795" ixy="1.498E-08" ixz="0.0023031" iyx="1.498E-08" iyy="0.028293" iyz="1.7726E-08" izx="0.0023031" izy="1.7726E-08" izz="0.073391"/>
    </inertial>
    <visual>
      <geometry>
        <mesh filename="package://poli2_description/meshes/visual/110_caster_plate.dae"/>
      </geometry>
    </visual>
    <collision>
      <origin rpy="0 0 3.14159" xyz="0 0 0"/>
      <geometry>
        <mesh filename="package://poli2_description/meshes/collision/110_caster_plate_collision.stl"/>
      </geometry>
    </collision>
  </link>
  <link name="rear_caster_swivel_link">
    <inertial>
      <mass value="0.44313"/>
      <origin xyz="-0.026936 -0.00036449 -0.06084"/>
      <inertia ixx="0.00096872" ixy="1.7959E-06" ixz="0.00018091" iyx="1.7959E-06" iyy="0.00081859" iyz="7.3049E-06" izx="0.00018091" izy="7.3049E-06" izz="0.00050861"/>
    </inertial>
    <visual>
      <origin rpy="0 0 3.14159" xyz="0 0 0"/>
      <geometry>
        <mesh filename="package://poli2_description/meshes/visual/caster_bracket.dae"/>
      </geometry>
    </visual>
    <collision>
      <origin rpy="0 0 3.14159" xyz="0 0 0"/>
      <geometry>
        <mesh filename="package://poli2_description/meshes/collision/caster_bracket_collision.stl"/>
      </geometry>
    </collision>
  </link>
  <gazebo reference="rear_caster_swivel_link">
    <mu1 value="100.0"/>
    <mu2 value="100.0"/>
    <kp value="10000000.0"/>
    <kd value="1.0"/>
  </gazebo>
  <joint name="rear_caster_swivel" type="continuous">
    <parent link="rear_caster_plate_link"/>
    <child link="rear_caster_swivel_link"/>
    <!--xacro:insert_block name="joint_pose"/-->
    <axis xyz="0 0 1"/>
    <anchor xyz="0 0 0"/>
    <limit effort="0.0" velocity="1000"/>
    <dynamics damping="0.7"/>
  </joint>
  <transmission name="rear_caster_swivel_trans" type="SimpleTransmission">
    <type>transmission_interface/SimpleTransmission</type>
    <joint name="rear_caster_swivel">
      <hardwareInterface>EffortJointInterface</hardwareInterface>
    </joint>
    <actuator name="rear_caster_swivel_motor">
      <hardwareInterface>EffortJointInterface</hardwareInterface>
      <mechanicalReduction>1</mechanicalReduction>
    </actuator>
  </transmission>
  <link name="rear_caster_wheel_link">
    <inertial>
      <mass value="0.851657"/>
      <origin xyz="0.000008 -0.000532 0.000003"/>
      <inertia ixx="0.001215" ixy="0.000000" ixz="0.000000" iyx="0.000000" iyy="0.002170" iyz="0.000000" izx="0.000000" izy="0.000000" izz="0.001215"/>
    </inertial>
    <visual>
      <geometry>
        <mesh filename="package://poli2_description/meshes/visual/caster_wheel.dae"/>
      </geometry>
    </visual>
    <collision>
      <origin rpy="1.570795 0 0" xyz="0 0 0"/>
      <geometry>
        <cylinder length="0.050" radius="0.0762"/>
      </geometry>
    </collision>
  </link>
  <gazebo reference="rear_caster_wheel_link">
    <mu1 value="100.0"/>
    <mu2 value="100.0"/>
    <kp value="10000000.0"/>
    <kd value="10.0"/>
    <fdir1 value="1 0 0"/>
    <minDepth>0.003</minDepth>
  </gazebo>
  <joint name="rear_caster_wheel" type="continuous">
    <parent link="rear_caster_swivel_link"/>
    <child link="rear_caster_wheel_link"/>
    <origin rpy="0 0 0" xyz="0.03782 0 -0.10608"/>
    <axis xyz="0 1 0"/>
    <anchor xyz="-0.03782 0 -0.10608"/>
    <limit effort="0.0" velocity="1000"/>
    <dynamics damping="0.2"/>
  </joint>
  <transmission name="rear_caster_wheel_trans" type="SimpleTransmission">
    <type>transmission_interface/SimpleTransmission</type>
    <joint name="rear_caster_wheel">
      <hardwareInterface>EffortJointInterface</hardwareInterface>
    </joint>
    <actuator name="rear_caster_wheel_motor">
      <hardwareInterface>EffortJointInterface</hardwareInterface>
      <mechanicalReduction>1</mechanicalReduction>
    </actuator>
  </transmission>
  <joint name="front_caster_plate_joint" type="fixed">
    <origin rpy="0 0 0" xyz="0.32784550 0 0.03326933"/>
    <parent link="base_chassis_link"/>
    <child link="front_caster_plate_link"/>
  </joint>
  <link name="front_caster_plate_link">
    <inertial>
      <mass value="3.836"/>
      <origin xyz="0.060136 -8.6661E-08 0.039089"/>
      <inertia ixx="0.047795" ixy="1.498E-08" ixz="0.0023031" iyx="1.498E-08" iyy="0.028293" iyz="1.7726E-08" izx="0.0023031" izy="1.7726E-08" izz="0.073391"/>
    </inertial>
    <visual>
      <geometry>
        <mesh filename="package://poli2_description/meshes/visual/110_caster_plate.dae"/>
      </geometry>
    </visual>
    <collision>
      <origin rpy="0 0 3.14159" xyz="0 0 0"/>
      <geometry>
        <mesh filename="package://poli2_description/meshes/collision/110_caster_plate_collision.stl"/>
      </geometry>
    </collision>
  </link>
  <link name="front_caster_swivel_link">
    <inertial>
      <mass value="0.44313"/>
      <origin xyz="-0.026936 -0.00036449 -0.06084"/>
      <inertia ixx="0.00096872" ixy="1.7959E-06" ixz="0.00018091" iyx="1.7959E-06" iyy="0.00081859" iyz="7.3049E-06" izx="0.00018091" izy="7.3049E-06" izz="0.00050861"/>
    </inertial>
    <visual>
      <origin rpy="0 0 3.14159" xyz="0 0 0"/>
      <geometry>
        <mesh filename="package://poli2_description/meshes/visual/caster_bracket.dae"/>
      </geometry>
    </visual>
    <collision>
      <origin rpy="0 0 3.14159" xyz="0 0 0"/>
      <geometry>
        <mesh filename="package://poli2_description/meshes/collision/caster_bracket_collision.stl"/>
      </geometry>
    </collision>
  </link>
  <gazebo reference="front_caster_swivel_link">
    <mu1 value="100.0"/>
    <mu2 value="100.0"/>
    <kp value="10000000.0"/>
    <kd value="1.0"/>
  </gazebo>
  <joint name="front_caster_swivel" type="continuous">
    <parent link="front_caster_plate_link"/>
    <child link="front_caster_swivel_link"/>
    <!--xacro:insert_block name="joint_pose"/-->
    <axis xyz="0 0 1"/>
    <anchor xyz="0 0 0"/>
    <limit effort="0.0" velocity="1000"/>
    <dynamics damping="0.7"/>
  </joint>
  <transmission name="front_caster_swivel_trans" type="SimpleTransmission">
    <type>transmission_interface/SimpleTransmission</type>
    <joint name="front_caster_swivel">
      <hardwareInterface>EffortJointInterface</hardwareInterface>
    </joint>
    <actuator name="front_caster_swivel_motor">
      <hardwareInterface>EffortJointInterface</hardwareInterface>
      <mechanicalReduction>1</mechanicalReduction>
    </actuator>
  </transmission>
  <link name="front_caster_wheel_link">
    <inertial>
      <mass value="0.851657"/>
      <origin xyz="0.000008 -0.000532 0.000003"/>
      <inertia ixx="0.001215" ixy="0.000000" ixz="0.000000" iyx="0.000000" iyy="0.002170" iyz="0.000000" izx="0.000000" izy="0.000000" izz="0.001215"/>
    </inertial>
    <visual>
      <geometry>
        <mesh filename="package://poli2_description/meshes/visual/caster_wheel.dae"/>
      </geometry>
    </visual>
    <collision>
      <origin rpy="1.570795 0 0" xyz="0 0 0"/>
      <geometry>
        <cylinder length="0.050" radius="0.0762"/>
      </geometry>
    </collision>
  </link>
  <gazebo reference="front_caster_wheel_link">
    <mu1 value="100.0"/>
    <mu2 value="100.0"/>
    <kp value="10000000.0"/>
    <kd value="10.0"/>
    <fdir1 value="1 0 0"/>
    <minDepth>0.003</minDepth>
  </gazebo>
  <joint name="front_caster_wheel" type="continuous">
    <parent link="front_caster_swivel_link"/>
    <child link="front_caster_wheel_link"/>
    <origin rpy="0 0 0" xyz="0.03782 0 -0.10608"/>
    <axis xyz="0 1 0"/>
    <anchor xyz="-0.03782 0 -0.10608"/>
    <limit effort="0.0" velocity="1000"/>
    <dynamics damping="0.2"/>
  </joint>
  <transmission name="front_caster_wheel_trans" type="SimpleTransmission">
    <type>transmission_interface/SimpleTransmission</type>
    <joint name="front_caster_wheel">
      <hardwareInterface>EffortJointInterface</hardwareInterface>
    </joint>
    <actuator name="front_caster_wheel_motor">
      <hardwareInterface>EffortJointInterface</hardwareInterface>
      <mechanicalReduction>1</mechanicalReduction>
    </actuator>
  </transmission>
  <joint name="base_plate_joint" type="fixed">
    <origin rpy="1.57079 0 -1.57079" xyz="0.0762 0.16355 0.076"/>
    <parent link="base_chassis_link"/>
    <child link="base_plate_link"/>
  </joint>
  <link name="base_plate_link">
    <visual>
      <geometry>
        <mesh filename="package://poli2_description/meshes/components/base_plate.STL"/>
      </geometry>
      <material name="">
        <color rgba="0.5 0.5 0.5 1"/>
      </material>
    </visual>
    <collision>
      <geometry>
        <mesh filename="package://poli2_description/meshes/components/base_plate.STL"/>
      </geometry>
    </collision>
  </link>
  <joint name="rmp_plate2_joint" type="fixed">
    <origin rpy="0 0 0" xyz="-0.079 -0.016 0.075"/>
    <parent link="base_plate_link"/>
    <child link="rmp_plate2_link"/>
  </joint>
  <link name="rmp_plate2_link">
    <visual>
      <geometry>
        <mesh filename="package://poli2_description/meshes/components/rmp_plate2.STL"/>
      </geometry>
      <material name="">
        <color rgba="0.5 0.5 0.5 1"/>
      </material>
    </visual>
    <collision>
      <geometry>
        <mesh filename="package://poli2_description/meshes/components/rmp_plate2.STL"/>
      </geometry>
    </collision>
  </link>
  <joint name="rmp_plate3_joint" type="fixed">
    <origin rpy="3.14159 0 0" xyz="-0.079 0.048 0.075"/>
    <parent link="base_plate_link"/>
    <child link="rmp_plate3_link"/>
  </joint>
  <link name="rmp_plate3_link">
    <visual>
      <geometry>
        <mesh filename="package://poli2_description/meshes/components/rmp_plate3.STL"/>
      </geometry>
      <material name="">
        <color rgba="0.5 0.5 0.5 1"/>
      </material>
    </visual>
    <collision>
      <geometry>
        <mesh filename="package://poli2_description/meshes/components/rmp_plate3.STL"/>
      </geometry>
    </collision>
  </link>
  <joint name="pillar_base_joint" type="fixed">
    <origin rpy="0 -1.57079 0" xyz="0.2315586 0 0.0075"/>
    <parent link="base_plate_link"/>
    <child link="pillar_base_link"/>
  </joint>
  <link name="pillar_base_link">
    <visual>
      <geometry>
        <mesh filename="package://poli2_description/meshes/components/pillar_exterior.STL"/>
      </geometry>
      <material name="">
        <color rgba="0.75 0.75 0.75 1"/>
      </material>
    </visual>
    <collision>
      <geometry>
        <mesh filename="package://poli2_description/meshes/components/pillar_exterior.STL"/>
      </geometry>
    </collision>
  </link>
  <joint name="pillar_telescope_joint" type="prismatic">
    <origin rpy="0 -1.570796 0" xyz="0.2175586 0.1 0.02"/>
    <parent link="base_plate_link"/>
    <child link="pillar_telescope_link"/>
    <limit effort="30" lower="0.0" upper="0.4" velocity="1.0"/>
    <axis xyz="0 1 0"/>
  </joint>
  <link name="pillar_telescope_link">
    <visual>
      <geometry>
        <mesh filename="package://poli2_description/meshes/components/pillar_telescope.STL"/>
      </geometry>
      <material name="">
        <color rgba="0.3 0.3 0.3 1"/>
      </material>
    </visual>
    <collision>
      <geometry>
        <mesh filename="package://poli2_description/meshes/components/pillar_telescope.STL"/>
      </geometry>
    </collision>
  </link>
  <joint name="pillar_plate_joint" type="fixed">
    <origin rpy="0 0 0" xyz="-0.14899868 0.17604938 -0.14899868"/>
    <parent link="pillar_telescope_link"/>
    <child link="pillar_plate_link"/>
  </joint>
  <link name="pillar_plate_link">
    <visual>
      <geometry>
        <mesh filename="package://poli2_description/meshes/components/pillar_plate.STL"/>
      </geometry>
      <material name="">
        <color rgba="0.5 0.5 0.5 1"/>
      </material>
    </visual>
    <collision>
      <geometry>
        <mesh filename="package://poli2_description/meshes/components/pillar_plate.STL"/>
      </geometry>
    </collision>
  </link>
  <joint name="neck_base_joint" type="fixed">
    <origin rpy="-1.57079 0 0" xyz="0.2658 0.36 0.1915"/>
    <parent link="pillar_plate_link"/>
    <child link="neck_base_link"/>
    <limit effort="50" velocity="50"/>
  </joint>
  <link name="neck_base_link">
    <inertial>
      <origin rpy="0 0 0" xyz="0.0023997 -3.3244E-06 0.033447"/>
      <mass value="0.6796"/>
      <inertia ixx="0.0014012" ixy="9.4856E-09" ixz="-3.5218E-06" iyy="0.0010212" iyz="-7.8472E-10" izz="0.0010421"/>
    </inertial>
    <visual>
      <origin rpy="0 0 0" xyz="0 0 0"/>
      <geometry>
        <mesh filename="package://poli2_description/meshes/components/neck/base_link.STL"/>
      </geometry>
      <material name="">
        <color rgba="0.89804 0.91765 0.92941 1"/>
      </material>
    </visual>
    <collision>
      <origin rpy="0 0 0" xyz="0 0 0"/>
      <geometry>
        <mesh filename="package://poli2_description/meshes/components/neck/base_link.STL"/>
      </geometry>
    </collision>
  </link>
  <link name="pan_link">
    <inertial>
      <origin rpy="0 0 0" xyz="-0.00034561 -0.0064887 0.077201"/>
      <mass value="0.28209"/>
      <inertia ixx="0.00045437" ixy="-3.8199E-06" ixz="2.945E-06" iyy="0.00019445" iyz="3.612E-05" izz="0.00032985"/>
    </inertial>
    <visual>
      <origin rpy="0 0 0" xyz="0 0 0"/>
      <geometry>
        <mesh filename="package://poli2_description/meshes/components/neck/pan_link.STL"/>
      </geometry>
      <material name="">
        <color rgba="0.89804 0.91765 0.92941 1"/>
      </material>
    </visual>
    <collision>
      <origin rpy="0 0 0" xyz="0 0 0"/>
      <geometry>
        <mesh filename="package://poli2_description/meshes/components/neck/pan_link.STL"/>
      </geometry>
    </collision>
  </link>
  <joint name="pan_joint" type="revolute">
    <limit effort="10" lower="-1.54" upper="1.54" velocity="10"/>
    <origin rpy="0 0 0" xyz="0.0014145 0 0.0466"/>
    <parent link="neck_base_link"/>
    <child link="pan_link"/>
    <axis xyz="0 0 1"/>
  </joint>
  <link name="tilt_link">
    <inertial>
      <origin rpy="0 0 0" xyz="-0.0449449011423384 0.0505307759460616 -0.0582731595130051"/>
      <mass value="0.282648823094398"/>
      <inertia ixx="0.000800089809159035" ixy="0.000149569968914255" ixz="4.25601989889811E-05" iyy="0.00166070452096634" iyz="-5.10288056116621E-05" izz="0.00151354802293456"/>
    </inertial>
    <visual>
      <origin rpy="0 0 0" xyz="0 0 0"/>
      <geometry>
        <mesh filename="package://poli2_description/meshes/components/neck/tilt_link.STL"/>
      </geometry>
      <material name="">
        <color rgba="0.898039215686275 0.917647058823529 0.929411764705882 1"/>
      </material>
    </visual>
    <collision>
      <origin rpy="0 0 0" xyz="0 0 0"/>
      <geometry>
        <mesh filename="package://poli2_description/meshes/components/neck/tilt_link.STL"/>
      </geometry>
    </collision>
  </link>
  <joint name="tilt_joint" type="revolute">
    <limit effort="10.0" lower="-1.0471975512" upper="0.0" velocity="1.0"/>
    <origin rpy="1.5708 0 0" xyz="0 -0.05475 0.09675"/>
    <parent link="pan_link"/>
    <child link="tilt_link"/>
    <axis xyz="0 0 1"/>
  </joint>
  <transmission name="tilt_joint_trans">
    <type>transmission_interface/SimpleTransmission</type>
    <joint name="tilt_joint">
      <hardwareInterface>hardware_interface/PositionJointInterface</hardwareInterface>
    </joint>
    <actuator name="tilt_joint_actuator">
      <mechanicalReduction>29768</mechanicalReduction>
    </actuator>
  </transmission>
  <!-- ros_control plugin -->
  <gazebo>
    <plugin filename="libgazebo_ros_control.so" name="gazebo_ros_control">
      <robotNamespace>j2s7s300</robotNamespace>
      <robotSimType>gazebo_ros_control/DefaultRobotHWSim</robotSimType>
    </plugin>
  </gazebo>
  <link name="j2s7s300_link_base">
    <visual>
      <geometry>
        <mesh filename="package://kinova_description/meshes/base.dae"/>
      </geometry>
      <material name="carbon_fiber">
        <color rgba="0.792156862745098 0.819607843137255 0.933333333333333 1"/>
      </material>
    </visual>
    <collision>
      <geometry>
        <mesh filename="package://kinova_description/meshes/base.dae"/>
      </geometry>
    </collision>
    <inertial>
      <mass value="0.46784"/>
      <origin rpy="0 0 0" xyz="0 0 0.1255"/>
      <inertia ixx="0.000951270861568" ixy="0" ixz="0" iyy="0.000951270861568" iyz="0" izz="0.000374272"/>
    </inertial>
  </link>
  <joint name="j2s7s300_joint_base" type="fixed">
    <parent link="pillar_plate_link"/>
    <child link="j2s7s300_link_base"/>
    <axis xyz="0 0 0"/>
    <limit effort="2000" lower="0" upper="0" velocity="1"/>
    <origin rpy="-1.57079 -1.57079 0" xyz="0 0.05 0.0575"/>
    <dynamics damping="0.0" friction="0.0"/>
  </joint>
  <link name="j2s7s300_link_1">
    <visual>
      <geometry>
        <mesh filename="package://kinova_description/meshes/shoulder.dae"/>
      </geometry>
      <material name="carbon_fiber">
        <color rgba="0.792156862745098 0.819607843137255 0.933333333333333 1"/>
      </material>
    </visual>
    <visual>
      <geometry>
        <mesh filename="package://kinova_description/meshes/ring_big.STL"/>
      </geometry>
    </visual>
    <collision>
      <geometry>
        <mesh filename="package://kinova_description/meshes/shoulder.dae"/>
      </geometry>
    </collision>
    <inertial>
      <mass value="0.7477"/>
      <origin xyz="0 -0.002 -0.0605"/>
      <inertia ixx="0.00152031725204" ixy="0" ixz="0" iyy="0.00152031725204" iyz="0" izz="0.00059816"/>
    </inertial>
  </link>
  <joint name="j2s7s300_joint_1" type="continuous">
    <parent link="j2s7s300_link_base"/>
    <child link="j2s7s300_link_1"/>
    <axis xyz="0 0 1"/>
    <limit effort="2000" lower="-6.28318530718" upper="6.28318530718" velocity="1"/>
    <origin rpy="0 3.14159265359 0" xyz="0 0 0.15675"/>
    <dynamics damping="0.0" friction="0.0"/>
  </joint>
  <transmission name="j2s7s300_joint_1_trans">
    <type>transmission_interface/SimpleTransmission</type>
    <joint name="j2s7s300_joint_1">
      <hardwareInterface>PositionJointInterface</hardwareInterface>
    </joint>
    <actuator name="j2s7s300_joint_1_actuator">
      <mechanicalReduction>160</mechanicalReduction>
    </actuator>
  </transmission>
  <link name="j2s7s300_link_2">
    <visual>
      <geometry>
        <mesh filename="package://kinova_description/meshes/arm_half_1.dae"/>
      </geometry>
      <material name="carbon_fiber">
        <color rgba="0.792156862745098 0.819607843137255 0.933333333333333 1"/>
      </material>
    </visual>
    <visual>
      <geometry>
        <mesh filename="package://kinova_description/meshes/ring_big.STL"/>
      </geometry>
    </visual>
    <collision>
      <geometry>
        <mesh filename="package://kinova_description/meshes/arm_half_1.dae"/>
      </geometry>
    </collision>
    <inertial>
      <mass value="0.8447"/>
      <origin xyz="0 -0.103563213 0"/>
      <inertia ixx="0.00247073761701" ixy="0" ixz="0" iyy="0.000380115" iyz="0" izz="0.00247073761701"/>
    </inertial>
  </link>
  <joint name="j2s7s300_joint_2" type="revolute">
    <parent link="j2s7s300_link_1"/>
    <child link="j2s7s300_link_2"/>
    <axis xyz="0 0 1"/>
    <limit effort="2000" lower="0.523598775598" upper="5.75958653158" velocity="1"/>
    <origin rpy="-1.57079632679 0 3.14159265359" xyz="0 0.0016 -0.11875"/>
    <dynamics damping="0.0" friction="0.0"/>
  </joint>
  <transmission name="j2s7s300_joint_2_trans">
    <type>transmission_interface/SimpleTransmission</type>
    <joint name="j2s7s300_joint_2">
      <hardwareInterface>PositionJointInterface</hardwareInterface>
    </joint>
    <actuator name="j2s7s300_joint_2_actuator">
      <mechanicalReduction>160</mechanicalReduction>
    </actuator>
  </transmission>
  <link name="j2s7s300_link_3">
    <visual>
      <geometry>
        <mesh filename="package://kinova_description/meshes/arm_half_2.dae"/>
      </geometry>
      <material name="carbon_fiber">
        <color rgba="0.792156862745098 0.819607843137255 0.933333333333333 1"/>
      </material>
    </visual>
    <visual>
      <geometry>
        <mesh filename="package://kinova_description/meshes/ring_big.STL"/>
      </geometry>
    </visual>
    <collision>
      <geometry>
        <mesh filename="package://kinova_description/meshes/arm_half_2.dae"/>
      </geometry>
    </collision>
    <inertial>
      <mass value="0.8447"/>
      <origin xyz="0 0 -0.1022447445"/>
      <inertia ixx="0.00247073761701" ixy="0" ixz="0" iyy="0.00247073761701" iyz="0" izz="0.000380115"/>
    </inertial>
  </link>
  <joint name="j2s7s300_joint_3" type="continuous">
    <parent link="j2s7s300_link_2"/>
    <child link="j2s7s300_link_3"/>
    <axis xyz="0 0 1"/>
    <limit effort="2000" lower="-6.28318530718" upper="6.28318530718" velocity="1"/>
    <origin rpy="-1.57079632679 0 0" xyz="0 -0.205 0"/>
    <dynamics damping="0.0" friction="0.0"/>
  </joint>
  <transmission name="j2s7s300_joint_3_trans">
    <type>transmission_interface/SimpleTransmission</type>
    <joint name="j2s7s300_joint_3">
      <hardwareInterface>PositionJointInterface</hardwareInterface>
    </joint>
    <actuator name="j2s7s300_joint_3_actuator">
      <mechanicalReduction>160</mechanicalReduction>
    </actuator>
  </transmission>
  <link name="j2s7s300_link_4">
    <visual>
      <geometry>
        <mesh filename="package://kinova_description/meshes/forearm.dae"/>
      </geometry>
      <material name="carbon_fiber">
        <color rgba="0.792156862745098 0.819607843137255 0.933333333333333 1"/>
      </material>
    </visual>
    <visual>
      <geometry>
        <mesh filename="package://kinova_description/meshes/ring_small.STL"/>
      </geometry>
    </visual>
    <collision>
      <geometry>
        <mesh filename="package://kinova_description/meshes/forearm.dae"/>
      </geometry>
    </collision>
    <inertial>
      <mass value="0.6763"/>
      <origin xyz="0 0.081 -0.0086"/>
      <inertia ixx="0.00142022431908" ixy="0" ixz="0" iyy="0.000304335" iyz="0" izz="0.00142022431908"/>
    </inertial>
  </link>
  <joint name="j2s7s300_joint_4" type="revolute">
    <parent link="j2s7s300_link_3"/>
    <child link="j2s7s300_link_4"/>
    <axis xyz="0 0 1"/>
    <limit effort="2000" lower="0.523598775598" upper="5.75958653158" velocity="1"/>
    <origin rpy="1.57079632679 0 3.14159265359" xyz="0 0 -0.205"/>
    <dynamics damping="0.0" friction="0.0"/>
  </joint>
  <transmission name="j2s7s300_joint_4_trans">
    <type>transmission_interface/SimpleTransmission</type>
    <joint name="j2s7s300_joint_4">
      <hardwareInterface>PositionJointInterface</hardwareInterface>
    </joint>
    <actuator name="j2s7s300_joint_4_actuator">
      <mechanicalReduction>160</mechanicalReduction>
    </actuator>
  </transmission>
  <link name="j2s7s300_link_5">
    <visual>
      <geometry>
        <mesh filename="package://kinova_description/meshes/wrist_spherical_1.dae"/>
      </geometry>
      <material name="carbon_fiber">
        <color rgba="0.792156862745098 0.819607843137255 0.933333333333333 1"/>
      </material>
    </visual>
    <visual>
      <geometry>
        <mesh filename="package://kinova_description/meshes/ring_small.STL"/>
      </geometry>
    </visual>
    <collision>
      <geometry>
        <mesh filename="package://kinova_description/meshes/wrist_spherical_1.dae"/>
      </geometry>
    </collision>
    <inertial>
      <mass value="0.463"/>
      <origin xyz="0 0.0028848942 -0.0541932613"/>
      <inertia ixx="0.0004321316048" ixy="0" ixz="0" iyy="0.0004321316048" iyz="0" izz="9.26e-05"/>
    </inertial>
  </link>
  <joint name="j2s7s300_joint_5" type="continuous">
    <parent link="j2s7s300_link_4"/>
    <child link="j2s7s300_link_5"/>
    <axis xyz="0 0 1"/>
    <limit effort="2000" lower="-6.28318530718" upper="6.28318530718" velocity="1"/>
    <origin rpy="-1.57079632679 0 3.14159265359" xyz="0 0.2073 -0.0114"/>
    <dynamics damping="0.0" friction="0.0"/>
  </joint>
  <transmission name="j2s7s300_joint_5_trans">
    <type>transmission_interface/SimpleTransmission</type>
    <joint name="j2s7s300_joint_5">
      <hardwareInterface>PositionJointInterface</hardwareInterface>
    </joint>
    <actuator name="j2s7s300_joint_5_actuator">
      <mechanicalReduction>160</mechanicalReduction>
    </actuator>
  </transmission>
  <link name="j2s7s300_link_6">
    <visual>
      <geometry>
        <mesh filename="package://kinova_description/meshes/wrist_spherical_2.dae"/>
      </geometry>
      <material name="carbon_fiber">
        <color rgba="0.792156862745098 0.819607843137255 0.933333333333333 1"/>
      </material>
    </visual>
    <visual>
      <geometry>
        <mesh filename="package://kinova_description/meshes/ring_small.STL"/>
      </geometry>
    </visual>
    <collision>
      <geometry>
        <mesh filename="package://kinova_description/meshes/wrist_spherical_2.dae"/>
      </geometry>
    </collision>
    <inertial>
      <mass value="0.463"/>
      <origin xyz="0 0.0497208855 -0.0028562765"/>
      <inertia ixx="0.0004321316048" ixy="0" ixz="0" iyy="9.26e-05" iyz="0" izz="0.0004321316048"/>
    </inertial>
  </link>
  <joint name="j2s7s300_joint_6" type="revolute">
    <parent link="j2s7s300_link_5"/>
    <child link="j2s7s300_link_6"/>
    <axis xyz="0 0 1"/>
    <limit effort="2000" lower="0.523598775598" upper="5.75958653158" velocity="1"/>
    <origin rpy="1.57079632679 0 3.14159265359" xyz="0 0 -0.10375"/>
    <dynamics damping="0.0" friction="0.0"/>
  </joint>
  <transmission name="j2s7s300_joint_6_trans">
    <type>transmission_interface/SimpleTransmission</type>
    <joint name="j2s7s300_joint_6">
      <hardwareInterface>PositionJointInterface</hardwareInterface>
    </joint>
    <actuator name="j2s7s300_joint_6_actuator">
      <mechanicalReduction>160</mechanicalReduction>
    </actuator>
  </transmission>
  <!--
        <xacro:kinova_armlink link_name="${prefix}_link_7" link_mesh="${link_7_mesh}" use_ring_mesh="true" ring_mesh="ring_small" mesh_no="${link_7_mesh_no}"/>
        <xacro:kinova_armjoint joint_name="${prefix}_joint_7" type="${joint_7_type}" parent="${prefix}_link_6" child="${prefix}_link_7" joint_axis_xyz="${joint_7_axis_xyz}" joint_origin_xyz="${joint_7_origin_xyz}" joint_origin_rpy="${joint_7_origin_rpy}" joint_lower_limit="${joint_7_lower_limit}" joint_upper_limit="${joint_7_upper_limit}"/>    

        <xacro:kinova_virtual_link link_name="${prefix}_end_effector"/>
        <xacro:kinova_virtual_joint joint_name="${prefix}_joint_end_effector" type="${joint_end_effector_type}" parent="${prefix}_link_7" child="${prefix}_end_effector" joint_axis_xyz="${joint_end_effector_axis_xyz}" joint_origin_xyz="${joint_end_effector_origin_xyz}" joint_origin_rpy="${joint_end_effector_origin_rpy}" joint_lower_limit="0" joint_upper_limit="0"/>    

        <xacro:kinova_3fingers link_hand="${prefix}_link_7" prefix="${prefix}_"/>
        -->
  <!-- RAIL end-effector additions/modifications -->
  <joint name="j2s7s300_joint_7" type="continuous">
    <parent link="j2s7s300_link_6"/>
    <child link="j2s7s300_link_7"/>
    <origin rpy="1.57079632679 0 0" xyz="0 0.06075 0"/>
    <axis xyz="0 0 1"/>
    <limit effort="600.8" velocity="0.785"/>
    <dynamics damping="0.0" friction="0.0"/>
  </joint>
  <link name="j2s7s300_link_7">
    <visual>
      <geometry>
        <mesh filename="package://kinova_description/meshes/wrist_3.dae"/>
      </geometry>
    </visual>
    <collision>
      <geometry>
        <mesh filename="package://kinova_description/meshes/wrist_3.stl"/>
      </geometry>
    </collision>
  </link>
  <joint name="j2s7s300_ee_fixed_joint" type="fixed">
    <parent link="j2s7s300_link_7"/>
    <child link="j2s7s300_ee_base"/>
    <origin rpy="0 1.57079632679 0" xyz="0 0 -0.09380704"/>
  </joint>
  <link name="j2s7s300_ee_base"/>
  <joint name="j2s7s300_ee_gripper" type="fixed">
    <parent link="j2s7s300_ee_base"/>
    <child link="j2s7s300_ee_link"/>
    <origin xyz="0.13 0 0"/>
  </joint>
  <link name="j2s7s300_ee_link"/>
  <transmission name="j2s7s300_joint_7_trans">
    <type>transmission_interface/SimpleTransmission</type>
    <joint name="j2s7s300_joint_7">
      <hardwareInterface>PositionJointInterface</hardwareInterface>
    </joint>
    <actuator name="j2s7s300_joint_7_actuator">
      <mechanicalReduction>160</mechanicalReduction>
    </actuator>
  </transmission>
  <joint name="gripper_base_joint" type="fixed">
    <parent link="j2s7s300_ee_base"/>
    <child link="gripper_base_link"/>
    <origin rpy="0 0 0" xyz="0 0 0"/>
  </joint>
  <link name="gripper_base_link">
    <visual>
      <geometry>
        <mesh filename="package://robotiq_85_description/meshes/visual/robotiq_85_base_link.dae"/>
      </geometry>
    </visual>
    <collision>
      <geometry>
        <mesh filename="package://robotiq_85_description/meshes/collision/robotiq_85_base_link.stl"/>
      </geometry>
    </collision>
    <inertial>
      <mass value="0.636951"/>
      <origin xyz="0.0 0.0 0.0"/>
      <inertia ixx="0.000380" ixy="0.000000" ixz="0.000000" iyx="0.000000" iyy="0.001110" iyz="0.000000" izx="0.000000" izy="0.000000" izz="0.001171"/>
    </inertial>
  </link>
  <gazebo reference="gripper_base_link">
    <implicitSpringDamper>1</implicitSpringDamper>
    <mu1>100000</mu1>
    <mu2>100000</mu2>
    <kp>100000000.0</kp>
    <kd>1.0</kd>
  </gazebo>
  <joint name="gripper_finger1_joint" type="revolute">
    <parent link="gripper_base_link"/>
    <child link="gripper_finger1_knuckle_link"/>
    <axis xyz="0 0 1"/>
    <origin rpy="3.14159265359 0.0 0.0" xyz="0.05490451627 0.03060114443 0.0"/>
    <limit effort="1000" lower="0.0" upper="0.804" velocity="2.0"/>
  </joint>
  <joint name="gripper_finger2_joint" type="revolute">
    <parent link="gripper_base_link"/>
    <child link="gripper_finger2_knuckle_link"/>
    <axis xyz="0 0 1"/>
    <origin rpy="0.0 0.0 0.0" xyz="0.05490451627 -0.03060114443 0.0"/>
    <limit effort="1000" lower="-3.14" upper="3.14" velocity="100.0"/>
    <mimic joint="gripper_finger1_joint"/>
  </joint>
  <link name="gripper_finger1_knuckle_link">
    <visual>
      <geometry>
        <mesh filename="package://robotiq_85_description/meshes/visual/robotiq_85_knuckle_link.dae"/>
      </geometry>
    </visual>
    <collision>
      <geometry>
        <mesh filename="package://robotiq_85_description/meshes/collision/robotiq_85_knuckle_link.stl"/>
      </geometry>
    </collision>
    <inertial>
      <mass value="0.018491"/>
      <origin xyz="0.0 0.0 0.0"/>
      <inertia ixx="0.000009" ixy="-0.000001" ixz="0.000000" iyx="-0.000001" iyy="0.000001" iyz="0.000000" izx="0.000000" izy="0.000000" izz="0.000010"/>
    </inertial>
  </link>
  <gazebo reference="gripper_finger1_knuckle_link">
    <implicitSpringDamper>1</implicitSpringDamper>
    <mu1>100000</mu1>
    <mu2>100000</mu2>
    <kp>100000000.0</kp>
    <kd>1.0</kd>
  </gazebo>
  <link name="gripper_finger2_knuckle_link">
    <visual>
      <geometry>
        <mesh filename="package://robotiq_85_description/meshes/visual/robotiq_85_knuckle_link.dae"/>
      </geometry>
    </visual>
    <collision>
      <geometry>
        <mesh filename="package://robotiq_85_description/meshes/collision/robotiq_85_knuckle_link.stl"/>
      </geometry>
    </collision>
    <inertial>
      <mass value="0.018491"/>
      <origin xyz="0.0 0.0 0.0"/>
      <inertia ixx="0.000009" ixy="-0.000001" ixz="0.000000" iyx="-0.000001" iyy="0.000001" iyz="0.000000" izx="0.000000" izy="0.000000" izz="0.000010"/>
    </inertial>
  </link>
  <gazebo reference="gripper_finger2_knuckle_link">
    <implicitSpringDamper>1</implicitSpringDamper>
    <mu1>100000</mu1>
    <mu2>100000</mu2>
    <kp>100000000.0</kp>
    <kd>1.0</kd>
  </gazebo>
  <joint name="gripper_finger1_finger_joint" type="fixed">
    <parent link="gripper_finger1_knuckle_link"/>
    <child link="gripper_finger1_finger_link"/>
    <origin rpy="0 0 0" xyz="-0.00408552455 -0.03148604435 0.0"/>
  </joint>
  <joint name="gripper_finger2_finger_joint" type="fixed">
    <parent link="gripper_finger2_knuckle_link"/>
    <child link="gripper_finger2_finger_link"/>
    <origin rpy="0 0 0" xyz="-0.00408552455 -0.03148604435 0.0"/>
  </joint>
  <link name="gripper_finger1_finger_link">
    <visual>
      <geometry>
        <mesh filename="package://robotiq_85_description/meshes/visual/robotiq_85_finger_link.dae"/>
      </geometry>
    </visual>
    <collision>
      <geometry>
        <mesh filename="package://robotiq_85_description/meshes/collision/robotiq_85_finger_link.stl"/>
      </geometry>
    </collision>
    <inertial>
      <mass value="0.027309"/>
      <origin xyz="0.0 0.0 0.0"/>
      <inertia ixx="0.000003" ixy="-0.000002" ixz="0.000000" iyx="-0.000002" iyy="0.000021" iyz="0.000000" izx="0.000000" izy="0.000000" izz="0.000020"/>
    </inertial>
  </link>
  <gazebo reference="gripper_finger1_finger_link">
    <implicitSpringDamper>1</implicitSpringDamper>
    <mu1>100000</mu1>
    <mu2>100000</mu2>
    <kp>100000000.0</kp>
    <kd>1.0</kd>
  </gazebo>
  <link name="gripper_finger2_finger_link">
    <visual>
      <geometry>
        <mesh filename="package://robotiq_85_description/meshes/visual/robotiq_85_finger_link.dae"/>
      </geometry>
    </visual>
    <collision>
      <geometry>
        <mesh filename="package://robotiq_85_description/meshes/collision/robotiq_85_finger_link.stl"/>
      </geometry>
    </collision>
    <inertial>
      <mass value="0.027309"/>
      <origin xyz="0.0 0.0 0.0"/>
      <inertia ixx="0.000003" ixy="-0.000002" ixz="0.000000" iyx="-0.000002" iyy="0.000021" iyz="0.000000" izx="0.000000" izy="0.000000" izz="0.000020"/>
    </inertial>
  </link>
  <gazebo reference="gripper_finger2_finger_link">
    <implicitSpringDamper>1</implicitSpringDamper>
    <mu1>100000</mu1>
    <mu2>100000</mu2>
    <kp>100000000.0</kp>
    <kd>1.0</kd>
  </gazebo>
  <joint name="gripper_finger1_inner_knuckle_joint" type="continuous">
    <parent link="gripper_base_link"/>
    <child link="gripper_finger1_inner_knuckle_link"/>
    <axis xyz="0 0 1"/>
    <origin rpy="3.14159265359 0.0 0.0" xyz="0.06142 0.0127 0"/>
    <limit effort="0.1" lower="-3.14" upper="3.14" velocity="100.0"/>
    <mimic joint="gripper_finger1_joint" offset="0"/>
  </joint>
  <joint name="gripper_finger2_inner_knuckle_joint" type="continuous">
    <parent link="gripper_base_link"/>
    <child link="gripper_finger2_inner_knuckle_link"/>
    <axis xyz="0 0 1"/>
    <origin rpy="0 0 0" xyz="0.06142 -0.0127 0"/>
    <limit effort="0.1" lower="-3.14" upper="3.14" velocity="100.0"/>
    <mimic joint="gripper_finger1_joint" offset="0"/>
  </joint>
  <link name="gripper_finger1_inner_knuckle_link">
    <visual>
      <geometry>
        <mesh filename="package://robotiq_85_description/meshes/visual/robotiq_85_inner_knuckle_link.dae"/>
      </geometry>
    </visual>
    <collision>
      <geometry>
        <mesh filename="package://robotiq_85_description/meshes/collision/robotiq_85_inner_knuckle_link.stl"/>
      </geometry>
    </collision>
    <inertial>
      <mass value="0.029951"/>
      <origin xyz="0.0 0.0 0.0"/>
      <inertia ixx="0.000039" ixy="0.000000" ixz="0.000000" iyx="0.000000" iyy="0.000005" iyz="0.000000" izx="0.000000" izy="0.000000" izz="0.000035"/>
    </inertial>
  </link>
  <gazebo reference="gripper_finger1_inner_knuckle_link">
    <implicitSpringDamper>1</implicitSpringDamper>
    <mu1>100000</mu1>
    <mu2>100000</mu2>
    <kp>100000000.0</kp>
    <kd>1.0</kd>
  </gazebo>
  <link name="gripper_finger2_inner_knuckle_link">
    <visual>
      <geometry>
        <mesh filename="package://robotiq_85_description/meshes/visual/robotiq_85_inner_knuckle_link.dae"/>
      </geometry>
    </visual>
    <collision>
      <geometry>
        <mesh filename="package://robotiq_85_description/meshes/collision/robotiq_85_inner_knuckle_link.stl"/>
      </geometry>
    </collision>
    <inertial>
      <mass value="0.029951"/>
      <origin xyz="0.0 0.0 0.0"/>
      <inertia ixx="0.000039" ixy="0.000000" ixz="0.000000" iyx="0.000000" iyy="0.000005" iyz="0.000000" izx="0.000000" izy="0.000000" izz="0.000035"/>
    </inertial>
  </link>
  <gazebo reference="gripper_finger2_inner_knuckle_link">
    <implicitSpringDamper>1</implicitSpringDamper>
    <mu1>100000</mu1>
    <mu2>100000</mu2>
    <kp>100000000.0</kp>
    <kd>1.0</kd>
  </gazebo>
  <joint name="gripper_finger1_finger_tip_joint" type="continuous">
    <parent link="gripper_finger1_inner_knuckle_link"/>
    <child link="gripper_finger1_finger_tip_link"/>
    <axis xyz="0 0 1"/>
    <origin rpy="0.0 0.0 0.0" xyz="0.04303959807 -0.03759940821 0.0"/>
    <limit effort="0.1" lower="-3.14" upper="3.14" velocity="100.0"/>
    <mimic joint="gripper_finger1_joint" multiplier="-1"/>
  </joint>
  <joint name="gripper_finger2_finger_tip_joint" type="continuous">
    <parent link="gripper_finger2_inner_knuckle_link"/>
    <child link="gripper_finger2_finger_tip_link"/>
    <axis xyz="0 0 1"/>
    <origin rpy="0.0 0.0 0.0" xyz="0.04303959807 -0.03759940821  0.0"/>
    <limit effort="0.1" lower="-3.14" upper="3.14" velocity="100.0"/>
    <mimic joint="gripper_finger1_joint" multiplier="-1"/>
  </joint>
  <link name="gripper_finger1_finger_tip_link">
    <visual>
      <geometry>
        <mesh filename="package://robotiq_85_description/meshes/visual/robotiq_85_finger_tip_link.dae"/>
      </geometry>
    </visual>
    <collision>
      <geometry>
        <mesh filename="package://robotiq_85_description/meshes/collision/robotiq_85_finger_tip_link.stl"/>
      </geometry>
    </collision>
    <inertial>
      <mass value="0.019555"/>
      <origin xyz="0.0 0.0 0.0"/>
      <inertia ixx="0.000002" ixy="0.000000" ixz="0.000000" iyx="0.000000" iyy="0.000005" iyz="0.000000" izx="0.000000" izy="0.000000" izz="0.000006"/>
    </inertial>
  </link>
  <gazebo reference="gripper_finger1_finger_tip_link">
    <implicitSpringDamper>1</implicitSpringDamper>
    <mu1>100000</mu1>
    <mu2>100000</mu2>
    <kp>100000000.0</kp>
    <kd>1.0</kd>
  </gazebo>
  <link name="gripper_finger2_finger_tip_link">
    <visual>
      <geometry>
        <mesh filename="package://robotiq_85_description/meshes/visual/robotiq_85_finger_tip_link.dae"/>
      </geometry>
    </visual>
    <collision>
      <geometry>
        <mesh filename="package://robotiq_85_description/meshes/collision/robotiq_85_finger_tip_link.stl"/>
      </geometry>
    </collision>
    <inertial>
      <mass value="0.019555"/>
      <origin xyz="0.0 0.0 0.0"/>
      <inertia ixx="0.000002" ixy="0.000000" ixz="0.000000" iyx="0.000000" iyy="0.000005" iyz="0.000000" izx="0.000000" izy="0.000000" izz="0.000006"/>
    </inertial>
  </link>
  <gazebo reference="gripper_finger2_finger_tip_link">
    <implicitSpringDamper>1</implicitSpringDamper>
    <mu1>100000</mu1>
    <mu2>100000</mu2>
    <kp>100000000.0</kp>
    <kd>1.0</kd>
  </gazebo>
  <transmission name="gripper_finger1_trans">
    <type>transmission_interface/SimpleTransmission</type>
    <joint name="gripper_finger1_joint">
      <hardwareInterface>PositionJointInterface</hardwareInterface>
    </joint>
    <actuator name="gripper_finger1_motor">
      <mechanicalReduction>1</mechanicalReduction>
      <hardwareInterface>PositionJointInterface</hardwareInterface>
    </actuator>
  </transmission>
  <gazebo>
    <!-- loading plugin: mimic joints works in gazebo now -->
    <plugin filename="libroboticsgroup_gazebo_mimic_joint_plugin.so" name="mimic_robotiq_85_1">
      <joint>gripper_finger1_joint</joint>
      <mimicJoint>gripper_finger2_joint</mimicJoint>
      <!--multiplier>1.0</multiplier>
                <offset>0.0</offset-->
    </plugin>
    <plugin filename="libroboticsgroup_gazebo_mimic_joint_plugin.so" name="mimic_robotiq_85_2">
      <joint>gripper_finger1_joint</joint>
      <mimicJoint>gripper_finger2_inner_knuckle_joint</mimicJoint>
      <!--multiplier>1.0</multiplier>
                <offset>0.0</offset-->
    </plugin>
    <plugin filename="libroboticsgroup_gazebo_mimic_joint_plugin.so" name="mimic_robotiq_85_3">
      <joint>gripper_finger1_joint</joint>
      <mimicJoint>gripper_finger1_inner_knuckle_joint</mimicJoint>
      <!--multiplier>1.0</multiplier>
                <offset>0.0</offset-->
    </plugin>
    <plugin filename="libroboticsgroup_gazebo_mimic_joint_plugin.so" name="mimic_robotiq_85_4">
      <joint>gripper_finger1_joint</joint>
      <mimicJoint>gripper_finger1_finger_tip_joint</mimicJoint>
      <multiplier>-1.0</multiplier>
      <offset>0.0</offset>
    </plugin>
    <plugin filename="libroboticsgroup_gazebo_mimic_joint_plugin.so" name="mimic_robotiq_85_5">
      <joint>gripper_finger1_joint</joint>
      <mimicJoint>gripper_finger2_finger_tip_joint</mimicJoint>
      <multiplier>-1.0</multiplier>
      <offset>0.0</offset>
    </plugin>
  </gazebo>
  <joint name="rear_laser_joint" type="fixed">
    <origin rpy="-1.57079 -1.57079 0" xyz="0.242 0.075 0.33"/>
    <parent link="rmp_plate2_link"/>
    <child link="rear_laser_link"/>
  </joint>
  <link name="rear_laser_link">
    <visual>
      <geometry>
        <mesh filename="package://poli2_description/meshes/visual/sensors/hokuyo_ustlx.dae"/>
      </geometry>
    </visual>
    <collision>
      <geometry>
        <mesh filename="package://poli2_description/meshes/visual/sensors/hokuyo_ustlx.dae"/>
      </geometry>
    </collision>
  </link>
  <gazebo reference="rear_laser_link">
    <sensor name="rear_hokuyo_laser" type="ray">
      <pose>0 0 0 0 0 0</pose>
      <visualize>false</visualize>
      <update_rate>40</update_rate>
      <ray>
        <scan>
          <horizontal>
            <samples>720</samples>
            <resolution>1</resolution>
            <min_angle>-1.5078</min_angle>
            <max_angle>1.5078</max_angle>
          </horizontal>
        </scan>
        <range>
          <min>0.10</min>
          <max>30.0</max>
          <resolution>0.01</resolution>
        </range>
        <noise>
          <type>gaussian</type>
          <mean>0.0</mean>
          <stddev>0.01</stddev>
        </noise>
      </ray>
      <plugin filename="libgazebo_ros_laser.so" name="hokuyo_node">
        <topicName>/segway/rear_scan</topicName>
        <frameName>/segway/rear_laser_link</frameName>
      </plugin>
    </sensor>
  </gazebo>
  <joint name="front_laser_joint" type="fixed">
    <origin rpy="1.57079 -1.57079 0" xyz="0.242 -0.015 0.33"/>
    <parent link="rmp_plate3_link"/>
    <child link="front_laser_link"/>
  </joint>
  <link name="front_laser_link">
    <visual>
      <geometry>
        <mesh filename="package://poli2_description/meshes/visual/sensors/hokuyo_ustlx.dae"/>
      </geometry>
    </visual>
    <collision>
      <geometry>
        <mesh filename="package://poli2_description/meshes/visual/sensors/hokuyo_ustlx.dae"/>
      </geometry>
    </collision>
  </link>
  <gazebo reference="front_laser_link">
    <sensor name="front_hokuyo_laser" type="ray">
      <pose>0 0 0 0 0 0</pose>
      <visualize>false</visualize>
      <update_rate>40</update_rate>
      <ray>
        <scan>
          <horizontal>
            <samples>720</samples>
            <resolution>1</resolution>
            <min_angle>-1.5078</min_angle>
            <max_angle>1.5078</max_angle>
          </horizontal>
        </scan>
        <range>
          <min>0.10</min>
          <max>10.0</max>
          <resolution>0.01</resolution>
        </range>
        <noise>
          <type>gaussian</type>
          <mean>0.0</mean>
          <stddev>0.01</stddev>
        </noise>
      </ray>
      <plugin filename="libgazebo_ros_laser.so" name="hokuyo_node">
        <topicName>/segway/front_scan</topicName>
        <frameName>/segway/front_laser_link</frameName>
      </plugin>
    </sensor>
  </gazebo>
  <joint name="camera_rgb_joint" type="fixed">
    <origin rpy="1.57079 0 4.18879" xyz="-0.22 0.0 -0.0624 "/>
    <parent link="tilt_link"/>
    <child link="camera_rgb_frame"/>
  </joint>
  <link name="camera_rgb_frame"/>
  <joint name="camera_rgb_optical_joint" type="fixed">
    <origin rpy="-1.570795 0 -1.570795" xyz="0 0 0"/>
    <parent link="camera_rgb_frame"/>
    <child link="camera_rgb_optical_frame"/>
  </joint>
  <link name="camera_rgb_optical_frame"/>
  <joint name="camera_joint" type="fixed">
    <origin rpy="0 0 0" xyz="0 -0.0125 0"/>
    <parent link="camera_rgb_frame"/>
    <child link="camera_link"/>
  </joint>
  <link name="camera_link">
    <visual>
      <origin rpy="1.570795 0 1.570795" xyz="-0.04 0.02 -0.01"/>
      <geometry>
        <mesh filename="package://poli2_description/meshes/sensors/astra.dae" scale="1 1 1"/>
      </geometry>
    </visual>
    <collision>
      <origin rpy="0 0 0" xyz="0.0 0.0 0.0"/>
      <geometry>
        <box size="0.0400 0.1650 0.0300"/>
      </geometry>
    </collision>
    <inertial>
      <mass value="0.564"/>
      <origin xyz="0 0 0"/>
      <inertia ixx="0.003881243" ixy="0.0" ixz="0.0" iyy="0.000498940" iyz="0.0" izz="0.003879257"/>
    </inertial>
  </link>
  <joint name="camera_depth_joint" type="fixed">
    <origin rpy="0 0 0" xyz="0 0.025 0"/>
    <parent link="camera_rgb_frame"/>
    <child link="camera_depth_frame"/>
  </joint>
  <link name="camera_depth_frame"/>
  <joint name="camera_depth_optical_joint" type="fixed">
    <origin rpy="-1.570795 0 -1.570795" xyz="0 0 0"/>
    <parent link="camera_depth_frame"/>
    <child link="camera_depth_optical_frame"/>
  </joint>
  <link name="camera_depth_optical_frame"/>
  <joint name="sonar_joint" type="fixed">
    <origin rpy="1.57079 0 3.14158" xyz="0.007 0.022 0.203"/>
    <parent link="pillar_plate_link"/>
    <child link="sonar_link_1"/>
  </joint>
  <link name="sonar_link_1">
    <visual>
      <origin rpy="1.570795 0 1.570795" xyz="0 0 0"/>
      <geometry>
        <mesh filename="package://poli2_description/meshes/components/sonar_mount_1.STL"/>
      </geometry>
    </visual>
    <collision>
      <origin rpy="0 0 0" xyz="0.0 0.0 0.0"/>
      <geometry>
        <mesh filename="package://poli2_description/meshes/components/sonar_mount_1.STL"/>
      </geometry>
    </collision>
    <inertial>
      <mass value="0.564"/>
      <origin xyz="0 0 0"/>
      <inertia ixx="0.003881243" ixy="0.0" ixz="0.0" iyy="0.000498940" iyz="0.0" izz="0.003879257"/>
    </inertial>
  </link>
  <!-- simulation info -->
  <gazebo reference="sonar_link_1">
    <sensor name="sonar" type="ray">
      <always_on>true</always_on>
      <update_rate>10</update_rate>
      <pose>0 0 0 0 0 0</pose>
      <visualize>false</visualize>
      <ray>
        <scan>
          <horizontal>
            <samples>30</samples>
            <resolution>1</resolution>
            <min_angle>-.2</min_angle>
            <max_angle> .2</max_angle>
          </horizontal>
          <vertical>
            <samples>30</samples>
            <resolution>1</resolution>
            <min_angle>-.2</min_angle>
            <max_angle> .2</max_angle>
          </vertical>
        </scan>
        <range>
          <min>.2</min>
          <max>1.0</max>
          <resolution>0.01</resolution>
        </range>
      </ray>
      <plugin filename="libhector_gazebo_ros_sonar.so" name="gazebo_ros_sonar_controller">
        <gaussianNoise>0.005</gaussianNoise>
        <topicName>/sonar</topicName>
        <frameId>sonar_link</frameId>
      </plugin>
    </sensor>
  </gazebo>
</robot>

