<?xml version="1.0" ?>
<!-- =================================================================================== -->
<!-- |    This document was autogenerated by xacro from poli_wrapper.urdf.xacro        | -->
<!-- |    EDITING THIS FILE BY HAND IS NOT RECOMMENDED                                 | -->
<!-- =================================================================================== -->
<robot name="segway_robot" xmlns:body="http://playerstage.sourceforge.net/gazebo/xmlschema/#body" xmlns:controller="http://playerstage.sourceforge.net/gazebo/xmlschema/#controller" xmlns:gazebo="http://playerstage.sourceforge.net/gazebo/xmlschema/#gz" xmlns:geom="http://playerstage.sourceforge.net/gazebo/xmlschema/#geom" xmlns:interface="http://playerstage.sourceforge.net/gazebo/xmlschema/#interface" xmlns:joint="http://playerstage.sourceforge.net/gazebo/xmlschema/#joint" xmlns:model="http://playerstage.sourceforge.net/gazebo/xmlschema/#model" xmlns:physics="http://playerstage.sourceforge.net/gazebo/xmlschema/#physics" xmlns:renderable="http://playerstage.sourceforge.net/gazebo/xmlschema/#renderable" xmlns:rendering="http://playerstage.sourceforge.net/gazebo/xmlschema/#rendering" xmlns:sensor="http://playerstage.sourceforge.net/gazebo/xmlschema/#sensor" xmlns:xacro="http://ros.org/wiki/xacro" xmlns:xi="http://www.w3.org/2001/XInclude">
  <!-- links      		mesh_no
   base           		0
   shoulder       		1
   arm            		2
   forearm        		3
   wrist          		4
   arm_mico       		5
   arm_half1 (7dof)		6
   arm_half2 (7dof)		7
   wrist_spherical_1  8
   wrist_spherical_2  9

   hand 3 finger  		55
   hand_2finger   		56
   finger_proximal		57
   finger_distal      58 
-->
  <!-- links      		mesh_no
   base           		0
   shoulder       		1
   arm            		2
   forearm        		3
   wrist          		4
   arm_mico       		5
   arm_half1 (7dof)		6
   arm_half2 (7dof)		7
   wrist_spherical_1  8
   wrist_spherical_2  9

   hand 3 finger  		55
   hand_2finger   		56
   finger_proximal		57
   finger_distal      58 
-->
  <gazebo>
    <plugin filename="libgazebo_ros_control.so" name="gazebo_ros_control">
      <robotNamespace>/</robotNamespace>
    </plugin>
    <plugin filename="libgazebo_ros_force_based_move.so" name="object_controller">
      <commandTopic>/cmd_vel</commandTopic>
      <odometryTopic>/odom</odometryTopic>
      <odometryFrame>odom</odometryFrame>
      <odometryRate>30.0</odometryRate>
      <robotBaseFrame>base_link</robotBaseFrame>
      <publishOdometryTf>1</publishOdometryTf>
      <yaw_velocity_p_gain>100.0</yaw_velocity_p_gain>
      <x_velocity_p_gain>10000.0</x_velocity_p_gain>
      <y_velocity_p_gain>10000.0</y_velocity_p_gain>
    </plugin>
  </gazebo>
  <!-- Base link is the center of the robot's chassis between the motors projected on the ground -->
  <link name="base_link"/>
  <joint name="base_chassis_joint" type="fixed">
    <origin rpy="0 0 0" xyz="0 0 0.15801795"/>
    <parent link="base_link"/>
    <child link="base_chassis_link"/>
  </joint>
  <link name="base_chassis_link">
    <visual>
      <geometry>
        <mesh filename="package://poli2_description/meshes/visual/110_powerbase.dae"/>
      </geometry>
    </visual>
  </link>
  <link name="inertial_collision_link">
    <inertial>
      <mass value="29.756375"/>
      <origin xyz="0.001751 0.000008 0.018544"/>
      <inertia ixx="0.696269" ixy="0.016133" ixz="0.003232" iyx="0.016133" iyy="0.299110" iyz="-0.000004" izx="-0.077476" izy="-0.000004" izz="0.864394"/>
    </inertial>
    <collision>
      <geometry>
        <mesh filename="package://poli2_description/meshes/collision/110_powerbase_collision.stl"/>
      </geometry>
    </collision>
  </link>
  <joint name="inertial_collision_joint" type="fixed">
    <parent link="base_chassis_link"/>
    <child link="inertial_collision_link"/>
  </joint>
  <joint name="mcu_1_battery_joint" type="fixed">
    <origin rpy="0 0 0" xyz="-0.09298 0 0"/>
    <parent link="base_chassis_link"/>
    <child link="mcu_1_battery_link"/>
  </joint>
  <link name="mcu_1_battery_link">
    <visual>
      <geometry>
        <mesh filename="package://poli2_description/meshes/visual/battery.dae"/>
      </geometry>
    </visual>
  </link>
  <joint name="aux_battery_joint" type="fixed">
    <origin rpy="0 0 3.14159" xyz="0.09298 0 0"/>
    <parent link="base_chassis_link"/>
    <child link="aux_battery_link"/>
  </joint>
  <link name="aux_battery_link">
    <visual>
      <geometry>
        <mesh filename="package://poli2_description/meshes/visual/battery.dae"/>
      </geometry>
    </visual>
  </link>
  <joint name="hmi_joint" type="fixed">
    <origin rpy="0 0 0" xyz="0 0 0.09504494"/>
    <parent link="base_chassis_link"/>
    <child link="hmi_link"/>
  </joint>
  <link name="hmi_link">
    <visual>
      <geometry>
        <mesh filename="package://poli2_description/meshes/visual/110_hmi_box.dae"/>
      </geometry>
    </visual>
    <collision>
      <geometry>
        <mesh filename="package://poli2_description/meshes/collision/110_hmi_box_collision.stl"/>
      </geometry>
    </collision>
    <inertial>
      <mass value="0.078971"/>
      <origin xyz="-0.000022 -0.000090 0.035623"/>
      <inertia ixx="0.000082" ixy="0.000000" ixz="0.000000" iyx="0.000000" iyy="0.000081" iyz="-0.000001" izx="0.000000" izy="-0.000001" izz="0.000103"/>
    </inertial>
  </link>
  <joint name="hmi_plate_joint" type="fixed">
    <origin rpy="0 0 0" xyz="0 0 0"/>
    <parent link="hmi_link"/>
    <child link="hmi_plate_link"/>
  </joint>
  <link name="hmi_plate_link">
    <visual>
      <geometry>
        <mesh filename="package://poli2_description/meshes/visual/110_hmi_plate.dae"/>
      </geometry>
    </visual>
  </link>
  <link name="left_wheel_link">
    <inertial>
      <mass value="4.195729"/>
      <origin xyz="0 0 0"/>
      <inertia ixx="0.063680" ixy="0.000000" ixz="0.000000" iyx="0.000000" iyy="0.121410" iyz="0.000000" izx="0.000000" izy="0.000000" izz="0.063680"/>
    </inertial>
    <visual>
      <origin rpy="0 0 0.0" xyz="0 0 0"/>
      <geometry>
        <mesh filename="package://poli2_description/meshes/visual/i2_wheel.dae"/>
      </geometry>
    </visual>
    <collision>
      <origin rpy="1.570795 0 0" xyz="0 0 0"/>
      <geometry>
        <cylinder length="0.092249" radius="0.2405681"/>
      </geometry>
    </collision>
  </link>
  <gazebo reference="left_wheel_link">
    <mu1 value="10.0"/>
    <mu2 value="10.0"/>
    <kp value="10000000.0"/>
    <kd value="10.0"/>
    <fdir1 value="1 0 0"/>
    <minDepth>0.003</minDepth>
  </gazebo>
  <joint name="left_wheel" type="continuous">
    <parent link="base_chassis_link"/>
    <child link="left_wheel_link"/>
    <origin rpy="0 0 0" xyz="0 0.2406122 0.08255015"/>
    <axis rpy="0 0 0" xyz="0 1 0"/>
  </joint>
  <transmission name="left_wheel_trans" type="SimpleTransmission">
    <type>transmission_interface/SimpleTransmission</type>
    <actuator name="left_wheel_motor">
      <mechanicalReduction>1</mechanicalReduction>
    </actuator>
    <joint name="left_wheel">
      <hardwareInterface>VelocityJointInterface</hardwareInterface>
    </joint>
  </transmission>
  <link name="right_wheel_link">
    <inertial>
      <mass value="4.195729"/>
      <origin xyz="0 0 0"/>
      <inertia ixx="0.063680" ixy="0.000000" ixz="0.000000" iyx="0.000000" iyy="0.121410" iyz="0.000000" izx="0.000000" izy="0.000000" izz="0.063680"/>
    </inertial>
    <visual>
      <origin rpy="0 0 3.14159" xyz="0 0 0"/>
      <geometry>
        <mesh filename="package://poli2_description/meshes/visual/i2_wheel.dae"/>
      </geometry>
    </visual>
    <collision>
      <origin rpy="1.570795 0 0" xyz="0 0 0"/>
      <geometry>
        <cylinder length="0.092249" radius="0.2405681"/>
      </geometry>
    </collision>
  </link>
  <gazebo reference="right_wheel_link">
    <mu1 value="10.0"/>
    <mu2 value="10.0"/>
    <kp value="10000000.0"/>
    <kd value="10.0"/>
    <fdir1 value="1 0 0"/>
    <minDepth>0.003</minDepth>
  </gazebo>
  <joint name="right_wheel" type="continuous">
    <parent link="base_chassis_link"/>
    <child link="right_wheel_link"/>
    <origin rpy="0 0 0" xyz="0 -0.2406122 0.08255015"/>
    <axis rpy="0 0 0" xyz="0 1 0"/>
  </joint>
  <transmission name="right_wheel_trans" type="SimpleTransmission">
    <type>transmission_interface/SimpleTransmission</type>
    <actuator name="right_wheel_motor">
      <mechanicalReduction>1</mechanicalReduction>
    </actuator>
    <joint name="right_wheel">
      <hardwareInterface>VelocityJointInterface</hardwareInterface>
    </joint>
  </transmission>
  <joint name="rear_caster_plate_joint" type="fixed">
    <origin rpy="0 0 3.14159" xyz="-0.32784550 0 0.03326933"/>
    <parent link="base_chassis_link"/>
    <child link="rear_caster_plate_link"/>
  </joint>
  <link name="rear_caster_plate_link">
    <inertial>
      <mass value="3.836"/>
      <origin xyz="0.060136 -8.6661E-08 0.039089"/>
      <inertia ixx="0.047795" ixy="1.498E-08" ixz="0.0023031" iyx="1.498E-08" iyy="0.028293" iyz="1.7726E-08" izx="0.0023031" izy="1.7726E-08" izz="0.073391"/>
    </inertial>
    <visual>
      <geometry>
        <mesh filename="package://poli2_description/meshes/visual/110_caster_plate.dae"/>
      </geometry>
    </visual>
    <collision>
      <origin rpy="0 0 3.14159" xyz="0 0 0"/>
      <geometry>
        <mesh filename="package://poli2_description/meshes/collision/110_caster_plate_collision.stl"/>
      </geometry>
    </collision>
  </link>
  <link name="rear_caster_swivel_link">
    <inertial>
      <mass value="0.44313"/>
      <origin xyz="-0.026936 -0.00036449 -0.06084"/>
      <inertia ixx="0.00096872" ixy="1.7959E-06" ixz="0.00018091" iyx="1.7959E-06" iyy="0.00081859" iyz="7.3049E-06" izx="0.00018091" izy="7.3049E-06" izz="0.00050861"/>
    </inertial>
    <visual>
      <origin rpy="0 0 3.14159" xyz="0 0 0"/>
      <geometry>
        <mesh filename="package://poli2_description/meshes/visual/caster_bracket.dae"/>
      </geometry>
    </visual>
    <collision>
      <origin rpy="0 0 3.14159" xyz="0 0 0"/>
      <geometry>
        <mesh filename="package://poli2_description/meshes/collision/caster_bracket_collision.stl"/>
      </geometry>
    </collision>
  </link>
  <gazebo reference="rear_caster_swivel_link">
    <mu1 value="100.0"/>
    <mu2 value="100.0"/>
    <kp value="10000000.0"/>
    <kd value="1.0"/>
  </gazebo>
  <joint name="rear_caster_swivel" type="continuous">
    <parent link="rear_caster_plate_link"/>
    <child link="rear_caster_swivel_link"/>
    <!--xacro:insert_block name="joint_pose"/-->
    <axis xyz="0 0 1"/>
    <anchor xyz="0 0 0"/>
    <limit effort="0.0" velocity="1000"/>
    <dynamics damping="0.7"/>
  </joint>
  <transmission name="rear_caster_swivel_trans" type="SimpleTransmission">
    <type>transmission_interface/SimpleTransmission</type>
    <joint name="rear_caster_swivel">
      <hardwareInterface>EffortJointInterface</hardwareInterface>
    </joint>
    <actuator name="rear_caster_swivel_motor">
      <hardwareInterface>EffortJointInterface</hardwareInterface>
      <mechanicalReduction>1</mechanicalReduction>
    </actuator>
  </transmission>
  <link name="rear_caster_wheel_link">
    <inertial>
      <mass value="0.851657"/>
      <origin xyz="0.000008 -0.000532 0.000003"/>
      <inertia ixx="0.001215" ixy="0.000000" ixz="0.000000" iyx="0.000000" iyy="0.002170" iyz="0.000000" izx="0.000000" izy="0.000000" izz="0.001215"/>
    </inertial>
    <visual>
      <geometry>
        <mesh filename="package://poli2_description/meshes/visual/caster_wheel.dae"/>
      </geometry>
    </visual>
    <collision>
      <origin rpy="1.570795 0 0" xyz="0 0 0"/>
      <geometry>
        <cylinder length="0.050" radius="0.0762"/>
      </geometry>
    </collision>
  </link>
  <gazebo reference="rear_caster_wheel_link">
    <mu1 value="100.0"/>
    <mu2 value="100.0"/>
    <kp value="10000000.0"/>
    <kd value="10.0"/>
    <fdir1 value="1 0 0"/>
    <minDepth>0.003</minDepth>
  </gazebo>
  <joint name="rear_caster_wheel" type="continuous">
    <parent link="rear_caster_swivel_link"/>
    <child link="rear_caster_wheel_link"/>
    <origin rpy="0 0 0" xyz="0.03782 0 -0.10608"/>
    <axis xyz="0 1 0"/>
    <anchor xyz="-0.03782 0 -0.10608"/>
    <limit effort="0.0" velocity="1000"/>
    <dynamics damping="0.2"/>
  </joint>
  <transmission name="rear_caster_wheel_trans" type="SimpleTransmission">
    <type>transmission_interface/SimpleTransmission</type>
    <joint name="rear_caster_wheel">
      <hardwareInterface>EffortJointInterface</hardwareInterface>
    </joint>
    <actuator name="rear_caster_wheel_motor">
      <hardwareInterface>EffortJointInterface</hardwareInterface>
      <mechanicalReduction>1</mechanicalReduction>
    </actuator>
  </transmission>
  <joint name="front_caster_plate_joint" type="fixed">
    <origin rpy="0 0 0" xyz="0.32784550 0 0.03326933"/>
    <parent link="base_chassis_link"/>
    <child link="front_caster_plate_link"/>
  </joint>
  <link name="front_caster_plate_link">
    <inertial>
      <mass value="3.836"/>
      <origin xyz="0.060136 -8.6661E-08 0.039089"/>
      <inertia ixx="0.047795" ixy="1.498E-08" ixz="0.0023031" iyx="1.498E-08" iyy="0.028293" iyz="1.7726E-08" izx="0.0023031" izy="1.7726E-08" izz="0.073391"/>
    </inertial>
    <visual>
      <geometry>
        <mesh filename="package://poli2_description/meshes/visual/110_caster_plate.dae"/>
      </geometry>
    </visual>
    <collision>
      <origin rpy="0 0 3.14159" xyz="0 0 0"/>
      <geometry>
        <mesh filename="package://poli2_description/meshes/collision/110_caster_plate_collision.stl"/>
      </geometry>
    </collision>
  </link>
  <link name="front_caster_swivel_link">
    <inertial>
      <mass value="0.44313"/>
      <origin xyz="-0.026936 -0.00036449 -0.06084"/>
      <inertia ixx="0.00096872" ixy="1.7959E-06" ixz="0.00018091" iyx="1.7959E-06" iyy="0.00081859" iyz="7.3049E-06" izx="0.00018091" izy="7.3049E-06" izz="0.00050861"/>
    </inertial>
    <visual>
      <origin rpy="0 0 3.14159" xyz="0 0 0"/>
      <geometry>
        <mesh filename="package://poli2_description/meshes/visual/caster_bracket.dae"/>
      </geometry>
    </visual>
    <collision>
      <origin rpy="0 0 3.14159" xyz="0 0 0"/>
      <geometry>
        <mesh filename="package://poli2_description/meshes/collision/caster_bracket_collision.stl"/>
      </geometry>
    </collision>
  </link>
  <gazebo reference="front_caster_swivel_link">
    <mu1 value="100.0"/>
    <mu2 value="100.0"/>
    <kp value="10000000.0"/>
    <kd value="1.0"/>
  </gazebo>
  <joint name="front_caster_swivel" type="continuous">
    <parent link="front_caster_plate_link"/>
    <child link="front_caster_swivel_link"/>
    <!--xacro:insert_block name="joint_pose"/-->
    <axis xyz="0 0 1"/>
    <anchor xyz="0 0 0"/>
    <limit effort="0.0" velocity="1000"/>
    <dynamics damping="0.7"/>
  </joint>
  <transmission name="front_caster_swivel_trans" type="SimpleTransmission">
    <type>transmission_interface/SimpleTransmission</type>
    <joint name="front_caster_swivel">
      <hardwareInterface>EffortJointInterface</hardwareInterface>
    </joint>
    <actuator name="front_caster_swivel_motor">
      <hardwareInterface>EffortJointInterface</hardwareInterface>
      <mechanicalReduction>1</mechanicalReduction>
    </actuator>
  </transmission>
  <link name="front_caster_wheel_link">
    <inertial>
      <mass value="0.851657"/>
      <origin xyz="0.000008 -0.000532 0.000003"/>
      <inertia ixx="0.001215" ixy="0.000000" ixz="0.000000" iyx="0.000000" iyy="0.002170" iyz="0.000000" izx="0.000000" izy="0.000000" izz="0.001215"/>
    </inertial>
    <visual>
      <geometry>
        <mesh filename="package://poli2_description/meshes/visual/caster_wheel.dae"/>
      </geometry>
    </visual>
    <collision>
      <origin rpy="1.570795 0 0" xyz="0 0 0"/>
      <geometry>
        <cylinder length="0.050" radius="0.0762"/>
      </geometry>
    </collision>
  </link>
  <gazebo reference="front_caster_wheel_link">
    <mu1 value="100.0"/>
    <mu2 value="100.0"/>
    <kp value="10000000.0"/>
    <kd value="10.0"/>
    <fdir1 value="1 0 0"/>
    <minDepth>0.003</minDepth>
  </gazebo>
  <joint name="front_caster_wheel" type="continuous">
    <parent link="front_caster_swivel_link"/>
    <child link="front_caster_wheel_link"/>
    <origin rpy="0 0 0" xyz="0.03782 0 -0.10608"/>
    <axis xyz="0 1 0"/>
    <anchor xyz="-0.03782 0 -0.10608"/>
    <limit effort="0.0" velocity="1000"/>
    <dynamics damping="0.2"/>
  </joint>
  <transmission name="front_caster_wheel_trans" type="SimpleTransmission">
    <type>transmission_interface/SimpleTransmission</type>
    <joint name="front_caster_wheel">
      <hardwareInterface>EffortJointInterface</hardwareInterface>
    </joint>
    <actuator name="front_caster_wheel_motor">
      <hardwareInterface>EffortJointInterface</hardwareInterface>
      <mechanicalReduction>1</mechanicalReduction>
    </actuator>
  </transmission>
  <joint name="base_plate_joint" type="fixed">
    <origin rpy="1.57079 0 -1.57079" xyz="0.0762 0.16355 0.076"/>
    <parent link="base_chassis_link"/>
    <child link="base_plate_link"/>
  </joint>
  <link name="base_plate_link">
    <visual>
      <geometry>
        <mesh filename="package://poli2_description/meshes/components/base_plate.STL"/>
      </geometry>
    </visual>
    <collision>
      <geometry>
        <mesh filename="package://poli2_description/meshes/components/base_plate.STL"/>
      </geometry>
    </collision>
  </link>
  <joint name="rmp_plate2_joint" type="fixed">
    <origin rpy="0 0 0" xyz="-0.079 -0.016 0.075"/>
    <parent link="base_plate_link"/>
    <child link="rmp_plate2_link"/>
  </joint>
  <link name="rmp_plate2_link">
    <visual>
      <geometry>
        <mesh filename="package://poli2_description/meshes/components/rmp_plate2.STL"/>
      </geometry>
    </visual>
    <collision>
      <geometry>
        <mesh filename="package://poli2_description/meshes/components/rmp_plate2.STL"/>
      </geometry>
    </collision>
  </link>
  <joint name="rmp_plate3_joint" type="fixed">
    <origin rpy="3.14159 0 0" xyz="-0.079 0.048 0.075"/>
    <parent link="base_plate_link"/>
    <child link="rmp_plate3_link"/>
  </joint>
  <link name="rmp_plate3_link">
    <visual>
      <geometry>
        <mesh filename="package://poli2_description/meshes/components/rmp_plate3.STL"/>
      </geometry>
    </visual>
    <collision>
      <geometry>
        <mesh filename="package://poli2_description/meshes/components/rmp_plate3.STL"/>
      </geometry>
    </collision>
  </link>
  <joint name="pillar_base_joint" type="fixed">
    <origin rpy="0 -1.57079 0" xyz="0.2315586 0 0.0075"/>
    <parent link="base_plate_link"/>
    <child link="pillar_base_link"/>
  </joint>
  <link name="pillar_base_link">
    <visual>
      <geometry>
        <mesh filename="package://poli2_description/meshes/components/pillar_exterior.STL"/>
      </geometry>
    </visual>
    <collision>
      <geometry>
        <mesh filename="package://poli2_description/meshes/components/pillar_exterior.STL"/>
      </geometry>
    </collision>
  </link>
  <joint name="pillar_telescope_joint" type="prismatic">
    <origin rpy="0 -1.570796 0" xyz="0.2175586 0.1 0.02"/>
    <parent link="base_plate_link"/>
    <child link="pillar_telescope_link"/>
    <limit effort="30" lower="0.0" upper="0.4" velocity="1.0"/>
    <axis xyz="0 1 0"/>
  </joint>
  <link name="pillar_telescope_link">
    <visual>
      <geometry>
        <mesh filename="package://poli2_description/meshes/components/pillar_telescope.STL"/>
      </geometry>
    </visual>
    <collision>
      <geometry>
        <mesh filename="package://poli2_description/meshes/components/pillar_telescope.STL"/>
      </geometry>
    </collision>
  </link>
  <joint name="pillar_plate_joint" type="fixed">
    <origin rpy="0 0 0" xyz="-0.14899868 0.17604938 -0.14899868"/>
    <parent link="pillar_telescope_link"/>
    <child link="pillar_plate_link"/>
  </joint>
  <link name="pillar_plate_link">
    <visual>
      <geometry>
        <mesh filename="package://poli2_description/meshes/components/pillar_plate.STL"/>
      </geometry>
    </visual>
    <collision>
      <geometry>
        <mesh filename="package://poli2_description/meshes/components/pillar_plate.STL"/>
      </geometry>
    </collision>
  </link>
  <!-- ros_control plugin -->
  <gazebo>
    <plugin filename="libgazebo_ros_control.so" name="gazebo_ros_control">
      <robotNamespace>j2s7s300</robotNamespace>
      <robotSimType>gazebo_ros_control/DefaultRobotHWSim</robotSimType>
    </plugin>
  </gazebo>
  <link name="j2s7s300_link_base">
    <visual>
      <geometry>
        <mesh filename="package://kinova_description/meshes/base.dae"/>
      </geometry>
      <material name="carbon_fiber">
        <color rgba="0.792156862745098 0.819607843137255 0.933333333333333 1"/>
      </material>
    </visual>
    <collision>
      <geometry>
        <mesh filename="package://kinova_description/meshes/base.dae"/>
      </geometry>
    </collision>
    <inertial>
      <mass value="0.46784"/>
      <origin rpy="0 0 0" xyz="0 0 0.1255"/>
      <inertia ixx="0.000951270861568" ixy="0" ixz="0" iyy="0.000951270861568" iyz="0" izz="0.000374272"/>
    </inertial>
  </link>
  <joint name="j2s7s300_joint_base" type="fixed">
    <parent link="pillar_plate_link"/>
    <child link="j2s7s300_link_base"/>
    <axis xyz="0 0 0"/>
    <limit effort="2000" lower="0" upper="0" velocity="1"/>
    <origin rpy="-1.57079 -1.57079 0" xyz="0 0 0"/>
    <dynamics damping="0.0" friction="0.0"/>
  </joint>
  <link name="j2s7s300_link_1">
    <visual>
      <geometry>
        <mesh filename="package://kinova_description/meshes/shoulder.dae"/>
      </geometry>
      <material name="carbon_fiber">
        <color rgba="0.792156862745098 0.819607843137255 0.933333333333333 1"/>
      </material>
    </visual>
    <visual>
      <geometry>
        <mesh filename="package://kinova_description/meshes/ring_big.STL"/>
      </geometry>
    </visual>
    <collision>
      <geometry>
        <mesh filename="package://kinova_description/meshes/shoulder.dae"/>
      </geometry>
    </collision>
    <inertial>
      <mass value="0.7477"/>
      <origin xyz="0 -0.002 -0.0605"/>
      <inertia ixx="0.00152031725204" ixy="0" ixz="0" iyy="0.00152031725204" iyz="0" izz="0.00059816"/>
    </inertial>
  </link>
  <joint name="j2s7s300_joint_1" type="continuous">
    <parent link="j2s7s300_link_base"/>
    <child link="j2s7s300_link_1"/>
    <axis xyz="0 0 1"/>
    <limit effort="2000" lower="-6.28318530718" upper="6.28318530718" velocity="1"/>
    <origin rpy="0 3.14159265359 0" xyz="0 0 0.15675"/>
    <dynamics damping="0.0" friction="0.0"/>
  </joint>
  <transmission name="j2s7s300_joint_1_trans">
    <type>transmission_interface/SimpleTransmission</type>
    <joint name="j2s7s300_joint_1">
      <hardwareInterface>PositionJointInterface</hardwareInterface>
    </joint>
    <actuator name="j2s7s300_joint_1_actuator">
      <mechanicalReduction>160</mechanicalReduction>
    </actuator>
  </transmission>
  <link name="j2s7s300_link_2">
    <visual>
      <geometry>
        <mesh filename="package://kinova_description/meshes/arm_half_1.dae"/>
      </geometry>
      <material name="carbon_fiber">
        <color rgba="0.792156862745098 0.819607843137255 0.933333333333333 1"/>
      </material>
    </visual>
    <visual>
      <geometry>
        <mesh filename="package://kinova_description/meshes/ring_big.STL"/>
      </geometry>
    </visual>
    <collision>
      <geometry>
        <mesh filename="package://kinova_description/meshes/arm_half_1.dae"/>
      </geometry>
    </collision>
    <inertial>
      <mass value="0.8447"/>
      <origin xyz="0 -0.103563213 0"/>
      <inertia ixx="0.00247073761701" ixy="0" ixz="0" iyy="0.000380115" iyz="0" izz="0.00247073761701"/>
    </inertial>
  </link>
  <joint name="j2s7s300_joint_2" type="revolute">
    <parent link="j2s7s300_link_1"/>
    <child link="j2s7s300_link_2"/>
    <axis xyz="0 0 1"/>
    <limit effort="2000" lower="0.523598775598" upper="5.75958653158" velocity="1"/>
    <origin rpy="-1.57079632679 0 3.14159265359" xyz="0 0.0016 -0.11875"/>
    <dynamics damping="0.0" friction="0.0"/>
  </joint>
  <transmission name="j2s7s300_joint_2_trans">
    <type>transmission_interface/SimpleTransmission</type>
    <joint name="j2s7s300_joint_2">
      <hardwareInterface>PositionJointInterface</hardwareInterface>
    </joint>
    <actuator name="j2s7s300_joint_2_actuator">
      <mechanicalReduction>160</mechanicalReduction>
    </actuator>
  </transmission>
  <link name="j2s7s300_link_3">
    <visual>
      <geometry>
        <mesh filename="package://kinova_description/meshes/arm_half_2.dae"/>
      </geometry>
      <material name="carbon_fiber">
        <color rgba="0.792156862745098 0.819607843137255 0.933333333333333 1"/>
      </material>
    </visual>
    <visual>
      <geometry>
        <mesh filename="package://kinova_description/meshes/ring_big.STL"/>
      </geometry>
    </visual>
    <collision>
      <geometry>
        <mesh filename="package://kinova_description/meshes/arm_half_2.dae"/>
      </geometry>
    </collision>
    <inertial>
      <mass value="0.8447"/>
      <origin xyz="0 0 -0.1022447445"/>
      <inertia ixx="0.00247073761701" ixy="0" ixz="0" iyy="0.00247073761701" iyz="0" izz="0.000380115"/>
    </inertial>
  </link>
  <joint name="j2s7s300_joint_3" type="continuous">
    <parent link="j2s7s300_link_2"/>
    <child link="j2s7s300_link_3"/>
    <axis xyz="0 0 1"/>
    <limit effort="2000" lower="-6.28318530718" upper="6.28318530718" velocity="1"/>
    <origin rpy="-1.57079632679 0 0" xyz="0 -0.205 0"/>
    <dynamics damping="0.0" friction="0.0"/>
  </joint>
  <transmission name="j2s7s300_joint_3_trans">
    <type>transmission_interface/SimpleTransmission</type>
    <joint name="j2s7s300_joint_3">
      <hardwareInterface>PositionJointInterface</hardwareInterface>
    </joint>
    <actuator name="j2s7s300_joint_3_actuator">
      <mechanicalReduction>160</mechanicalReduction>
    </actuator>
  </transmission>
  <link name="j2s7s300_link_4">
    <visual>
      <geometry>
        <mesh filename="package://kinova_description/meshes/forearm.dae"/>
      </geometry>
      <material name="carbon_fiber">
        <color rgba="0.792156862745098 0.819607843137255 0.933333333333333 1"/>
      </material>
    </visual>
    <visual>
      <geometry>
        <mesh filename="package://kinova_description/meshes/ring_small.STL"/>
      </geometry>
    </visual>
    <collision>
      <geometry>
        <mesh filename="package://kinova_description/meshes/forearm.dae"/>
      </geometry>
    </collision>
    <inertial>
      <mass value="0.6763"/>
      <origin xyz="0 0.081 -0.0086"/>
      <inertia ixx="0.00142022431908" ixy="0" ixz="0" iyy="0.000304335" iyz="0" izz="0.00142022431908"/>
    </inertial>
  </link>
  <joint name="j2s7s300_joint_4" type="revolute">
    <parent link="j2s7s300_link_3"/>
    <child link="j2s7s300_link_4"/>
    <axis xyz="0 0 1"/>
    <limit effort="2000" lower="0.523598775598" upper="5.75958653158" velocity="1"/>
    <origin rpy="1.57079632679 0 3.14159265359" xyz="0 0 -0.205"/>
    <dynamics damping="0.0" friction="0.0"/>
  </joint>
  <transmission name="j2s7s300_joint_4_trans">
    <type>transmission_interface/SimpleTransmission</type>
    <joint name="j2s7s300_joint_4">
      <hardwareInterface>PositionJointInterface</hardwareInterface>
    </joint>
    <actuator name="j2s7s300_joint_4_actuator">
      <mechanicalReduction>160</mechanicalReduction>
    </actuator>
  </transmission>
  <link name="j2s7s300_link_5">
    <visual>
      <geometry>
        <mesh filename="package://kinova_description/meshes/wrist_spherical_1.dae"/>
      </geometry>
      <material name="carbon_fiber">
        <color rgba="0.792156862745098 0.819607843137255 0.933333333333333 1"/>
      </material>
    </visual>
    <visual>
      <geometry>
        <mesh filename="package://kinova_description/meshes/ring_small.STL"/>
      </geometry>
    </visual>
    <collision>
      <geometry>
        <mesh filename="package://kinova_description/meshes/wrist_spherical_1.dae"/>
      </geometry>
    </collision>
    <inertial>
      <mass value="0.463"/>
      <origin xyz="0 0.0028848942 -0.0541932613"/>
      <inertia ixx="0.0004321316048" ixy="0" ixz="0" iyy="0.0004321316048" iyz="0" izz="9.26e-05"/>
    </inertial>
  </link>
  <joint name="j2s7s300_joint_5" type="continuous">
    <parent link="j2s7s300_link_4"/>
    <child link="j2s7s300_link_5"/>
    <axis xyz="0 0 1"/>
    <limit effort="2000" lower="-6.28318530718" upper="6.28318530718" velocity="1"/>
    <origin rpy="-1.57079632679 0 3.14159265359" xyz="0 0.2073 -0.0114"/>
    <dynamics damping="0.0" friction="0.0"/>
  </joint>
  <transmission name="j2s7s300_joint_5_trans">
    <type>transmission_interface/SimpleTransmission</type>
    <joint name="j2s7s300_joint_5">
      <hardwareInterface>PositionJointInterface</hardwareInterface>
    </joint>
    <actuator name="j2s7s300_joint_5_actuator">
      <mechanicalReduction>160</mechanicalReduction>
    </actuator>
  </transmission>
  <link name="j2s7s300_link_6">
    <visual>
      <geometry>
        <mesh filename="package://kinova_description/meshes/wrist_spherical_2.dae"/>
      </geometry>
      <material name="carbon_fiber">
        <color rgba="0.792156862745098 0.819607843137255 0.933333333333333 1"/>
      </material>
    </visual>
    <visual>
      <geometry>
        <mesh filename="package://kinova_description/meshes/ring_small.STL"/>
      </geometry>
    </visual>
    <collision>
      <geometry>
        <mesh filename="package://kinova_description/meshes/wrist_spherical_2.dae"/>
      </geometry>
    </collision>
    <inertial>
      <mass value="0.463"/>
      <origin xyz="0 0.0497208855 -0.0028562765"/>
      <inertia ixx="0.0004321316048" ixy="0" ixz="0" iyy="9.26e-05" iyz="0" izz="0.0004321316048"/>
    </inertial>
  </link>
  <joint name="j2s7s300_joint_6" type="revolute">
    <parent link="j2s7s300_link_5"/>
    <child link="j2s7s300_link_6"/>
    <axis xyz="0 0 1"/>
    <limit effort="2000" lower="0.523598775598" upper="5.75958653158" velocity="1"/>
    <origin rpy="1.57079632679 0 3.14159265359" xyz="0 0 -0.10375"/>
    <dynamics damping="0.0" friction="0.0"/>
  </joint>
  <transmission name="j2s7s300_joint_6_trans">
    <type>transmission_interface/SimpleTransmission</type>
    <joint name="j2s7s300_joint_6">
      <hardwareInterface>PositionJointInterface</hardwareInterface>
    </joint>
    <actuator name="j2s7s300_joint_6_actuator">
      <mechanicalReduction>160</mechanicalReduction>
    </actuator>
  </transmission>
  <joint name="j2s7s300_joint_7" type="continuous">
    <origin rpy="-1.57079632679 0 0" xyz="0 0.10375 0"/>
    <parent link="j2s7s300_link_6"/>
    <child link="j2s7s300_link_7"/>
    <axis xyz="0 0 -1"/>
    <limit effort="50" velocity="50"/>
  </joint>
  <link name="j2s7s300_link_7">
    <visual>
      <geometry>
        <mesh filename="package://poli2_description/meshes/components/weiss_mount.STL"/>
      </geometry>
    </visual>
    <collision>
      <geometry>
        <mesh filename="package://poli2_description/meshes/components/weiss_mount.STL"/>
      </geometry>
    </collision>
  </link>
  <joint name="wsg_50_gripper_base_joint" type="fixed">
    <origin rpy="0 0 -1.57079632679" xyz="0.0001 0 0.085"/>
    <parent link="j2s7s300_link_7"/>
    <child link="wsg_50_gripper_base_link"/>
  </joint>
  <link name="wsg_50_gripper_base_link">
    <inertial>
      <origin rpy="0 0 0" xyz="-6.56023314178677E-06 -0.00175309107853196 0.0266239521718502"/>
      <mass value="0.19187770361295"/>
      <inertia ixx="0.000259095961095666" ixy="-4.42589635811335E-08" ixz="-8.19503266406055E-09" iyy="6.70924748330843E-05" iyz="-6.65748470338111E-06" izz="0.000219527960705521"/>
    </inertial>
    <visual>
      <origin rpy="0 0 0" xyz="0 0 0"/>
      <geometry>
        <mesh filename="package://wsg_32_description/meshes/hand_link.STL"/>
      </geometry>
      <material name="">
        <color rgba="0.792156862745098 0.819607843137255 0.933333333333333 1"/>
      </material>
    </visual>
    <collision>
      <origin rpy="0 0 0" xyz="0 0 0"/>
      <geometry>
        <mesh filename="package://wsg_32_description/meshes/hand_link.STL"/>
      </geometry>
    </collision>
  </link>
  <link name="wsg_50_gripper_base_link_gripper_left">
    <inertial>
      <origin rpy="0 0 0" xyz="-2.850603053553E-05 -0.00191114285188175 0.00382933445364996"/>
      <mass value="3.41920163633724E-06"/>
      <inertia ixx="3.06504383705634E-10" ixy="5.74222476890191E-11" ixz="-2.40533503848462E-10" iyy="4.90275789305826E-10" iyz="6.8945176052368E-11" izz="2.18298925049827E-10"/>
    </inertial>
    <visual>
      <origin rpy="0 1.57079 0" xyz="-0.00725 0 0.0004"/>
      <geometry>
        <mesh filename="package://wsg_32_description/meshes/left_finger_link.STL"/>
      </geometry>
      <material name="">
        <color rgba="0.792156862745098 0.819607843137255 0.933333333333333 1"/>
      </material>
    </visual>
    <collision>
      <origin rpy="0 0 0" xyz="0 0 0"/>
      <geometry>
        <mesh filename="package://wsg_32_description/meshes/left_finger_link.STL"/>
      </geometry>
    </collision>
  </link>
  <joint name="wsg_50_gripper_base_joint_gripper_left" type="prismatic">
    <origin rpy="3.1416 -1.5708 0" xyz="-0.0003903 -0.0358 0.069014"/>
    <parent link="wsg_50_gripper_base_link"/>
    <child link="wsg_50_gripper_base_link_gripper_left"/>
    <axis xyz="0 1 0"/>
    <limit effort="0" lower="-0.028" upper="0" velocity="0"/>
  </joint>
  <link name="wsg_50_gripper_base_link_gripper_right">
    <inertial>
      <origin rpy="0 0 0" xyz="-2.72000777333109E-05 -0.00460993992652343 -0.00191114282807962"/>
      <mass value="3.41920163633724E-06"/>
      <inertia ixx="3.06504383705634E-10" ixy="2.40533503848236E-10" ixz="5.74222476899625E-11" iyy="2.18298925050368E-10" iyz="-6.89451760534347E-11" izz="4.90275789305286E-10"/>
    </inertial>
    <visual>
      <origin rpy="-1.57079 0  -1.57079" xyz="-0.00725 0 0.0004"/>
      <geometry>
        <mesh filename="package://wsg_32_description/meshes/right_finger_link.STL"/>
      </geometry>
      <material name="">
        <color rgba="0.792156862745098 0.819607843137255 0.933333333333333 1"/>
      </material>
    </visual>
    <collision>
      <origin rpy="0 0 0" xyz="0 0 0"/>
      <geometry>
        <mesh filename="package://wsg_32_description/meshes/right_finger_link.STL"/>
      </geometry>
    </collision>
  </link>
  <joint name="wsg_50_gripper_base_joint_gripper_right" type="prismatic">
    <origin rpy="1.5708 -1.5708 0" xyz="-0.0003903 0.0358 0.069012"/>
    <parent link="wsg_50_gripper_base_link"/>
    <child link="wsg_50_gripper_base_link_gripper_right"/>
    <axis xyz="0 0 -1"/>
    <limit effort="0" lower="-0.028" upper="0" velocity="0"/>
  </joint>
  <!-- add fingers to actuated segments -->
  <link name="wsg_50_gripper_right_universal_finger_link">
    <inertial>
      <origin rpy="0 0 0" xyz="0 0 0"/>
      <mass value="0.001"/>
      <inertia ixx="3.06504383705634E-10" ixy="2.40533503848236E-10" ixz="5.74222476899625E-11" iyy="2.18298925050368E-10" iyz="-6.89451760534347E-11" izz="4.90275789305286E-10"/>
    </inertial>
    <visual>
      <origin rpy="0 0 0" xyz="-0.00 0 0.00"/>
      <geometry>
        <mesh filename="package://wsg_32_description/meshes/universal_finger.STL"/>
      </geometry>
      <material name="">
        <color rgba="0.792156862745098 0.819607843137255 0.933333333333333 1"/>
      </material>
    </visual>
    <collision>
      <origin rpy="0 0 0" xyz="0 0 0"/>
      <geometry>
        <mesh filename="package://wsg_32_description/meshes/universal_finger.STL"/>
      </geometry>
    </collision>
  </link>
  <joint name="wsg_50_gripper_right_universal_finger_joint" type="fixed">
    <origin rpy="0 1.57079 -1.57079" xyz="0.00755 0.0 0.0049"/>
    <parent link="wsg_50_gripper_base_link_gripper_right"/>
    <child link="wsg_50_gripper_right_universal_finger_link"/>
  </joint>
  <link name="wsg_50_gripper_left_universal_finger_link">
    <inertial>
      <origin rpy="0 0 0" xyz="0 0 0"/>
      <mass value="0.001"/>
      <inertia ixx="3.06504383705634E-10" ixy="2.40533503848236E-10" ixz="5.74222476899625E-11" iyy="2.18298925050368E-10" iyz="-6.89451760534347E-11" izz="4.90275789305286E-10"/>
    </inertial>
    <visual>
      <origin rpy="0 0 0" xyz="-0.00 0 0.00"/>
      <geometry>
        <mesh filename="package://wsg_32_description/meshes/universal_finger.STL"/>
      </geometry>
      <material name="">
        <color rgba="0.792156862745098 0.819607843137255 0.933333333333333 1"/>
      </material>
    </visual>
    <collision>
      <origin rpy="0 0 0" xyz="0 0 0"/>
      <geometry>
        <mesh filename="package://wsg_32_description/meshes/universal_finger.STL"/>
      </geometry>
    </collision>
  </link>
  <joint name="wsg_50_gripper_left_universal_finger_joint" type="fixed">
    <origin rpy="0 3.14159 -1.57079" xyz="0.00755 -0.0045 0"/>
    <parent link="wsg_50_gripper_base_link_gripper_left"/>
    <child link="wsg_50_gripper_left_universal_finger_link"/>
  </joint>
  <joint name="rear_laser_joint" type="fixed">
    <origin rpy="-1.57079 -1.57079 0" xyz="0.242 0.075 0.33"/>
    <parent link="rmp_plate2_link"/>
    <child link="rear_laser_link"/>
  </joint>
  <link name="rear_laser_link">
    <visual>
      <geometry>
        <mesh filename="package://poli2_description/meshes/visual/sensors/hokuyo_ustlx.dae"/>
      </geometry>
    </visual>
    <collision>
      <geometry>
        <mesh filename="package://poli2_description/meshes/visual/sensors/hokuyo_ustlx.dae"/>
      </geometry>
    </collision>
  </link>
  <gazebo reference="rear_laser_link">
    <sensor name="rear_hokuyo_laser" type="ray">
      <pose>0 0 0 0 0 0</pose>
      <visualize>false</visualize>
      <update_rate>40</update_rate>
      <ray>
        <scan>
          <horizontal>
            <samples>720</samples>
            <resolution>1</resolution>
            <min_angle>-1.5078</min_angle>
            <max_angle>1.5078</max_angle>
          </horizontal>
        </scan>
        <range>
          <min>0.10</min>
          <max>30.0</max>
          <resolution>0.01</resolution>
        </range>
        <noise>
          <type>gaussian</type>
          <mean>0.0</mean>
          <stddev>0.01</stddev>
        </noise>
      </ray>
      <plugin filename="libgazebo_ros_laser.so" name="hokuyo_node">
        <topicName>/segway/rear_scan</topicName>
        <frameName>/segway/rear_laser_link</frameName>
      </plugin>
    </sensor>
  </gazebo>
  <joint name="front_laser_joint" type="fixed">
    <origin rpy="1.57079 -1.57079 0" xyz="0.242 -0.015 0.33"/>
    <parent link="rmp_plate3_link"/>
    <child link="front_laser_link"/>
  </joint>
  <link name="front_laser_link">
    <visual>
      <geometry>
        <mesh filename="package://poli2_description/meshes/visual/sensors/hokuyo_ustlx.dae"/>
      </geometry>
    </visual>
    <collision>
      <geometry>
        <mesh filename="package://poli2_description/meshes/visual/sensors/hokuyo_ustlx.dae"/>
      </geometry>
    </collision>
  </link>
  <gazebo reference="front_laser_link">
    <sensor name="front_hokuyo_laser" type="ray">
      <pose>0 0 0 0 0 0</pose>
      <visualize>false</visualize>
      <update_rate>40</update_rate>
      <ray>
        <scan>
          <horizontal>
            <samples>720</samples>
            <resolution>1</resolution>
            <min_angle>-1.5078</min_angle>
            <max_angle>1.5078</max_angle>
          </horizontal>
        </scan>
        <range>
          <min>0.10</min>
          <max>10.0</max>
          <resolution>0.01</resolution>
        </range>
        <noise>
          <type>gaussian</type>
          <mean>0.0</mean>
          <stddev>0.01</stddev>
        </noise>
      </ray>
      <plugin filename="libgazebo_ros_laser.so" name="hokuyo_node">
        <topicName>/segway/front_scan</topicName>
        <frameName>/segway/front_laser_link</frameName>
      </plugin>
    </sensor>
  </gazebo>
</robot>
